Workbook

Sheet 5月全部
A1: 券类型 （联合券/单品牌券） | B1: 配券方式 （自配/其他） | C1: 活动时间 （非全月的需要标红） | D1: 机制名称 （务必与实际创建活动保持一致） | E1: 预算来源 | F1: 渠道类型 | G1: 区域 | H1: 渠道名称 | I1: 活动产品 | J1: 力度 | K1: 券名称 | L1: 预算 | M1: 优惠类型 (同享/互斥） | N1: 活动id | O1: 备注 | P1: 入口名称 | Q1: 子方案名称 | R1: 填写时间 | S1: 批次 | T1: 进度反馈 | U1: 生效情况
A2: 单品牌券 | B2: 三方混补 | C2: 5.1-5.31 | D2: 总-青啤全国快送熊-5月满59减20（品12） | E2: 总部 | F2: 闪电仓 | G2: 全国 | H2: 快送熊 | J2: 满59减20（品12） | K2: 青岛啤酒畅饮券 | L2: 15000 | M2: 互斥 | N2: 75990861 | P2: 76128413【26年5月青岛啤酒共补】 | Q2: 青岛啤酒-闪电仓 | R2: 4.21 | S2: 第一批 | T2: 已提报
A3: 单品牌券 | B3: 自配 | C3: 5.1-5.31 | D3: 总-青啤全国酒驿栈-5月满59减12 | E3: 总部 | F3: 酒专营 | G3: 全国 | H3: 酒驿栈 | J3: 满59减12 | K3: 青岛啤酒全国券 | L3: 10000 | M3: 同享 | R3: 4.21 | S3: 第一批 | T3: 已提报
A4: 单品牌券 | B4: 自配 | C4: 5.1-5.31 | D4: 总-青啤全国酒驿栈-5月满99减20 | E4: 总部 | F4: 酒专营 | G4: 全国 | H4: 酒驿栈 | J4: 满99减20 | K4: 青岛啤酒全国券 | L4: 10000 | M4: 同享 | R4: 4.21 | S4: 第一批 | T4: 已提报
A5: 单品牌券 | B5: 三方混补 | C5: 5.1-5.31 | D5: 总-青啤全国酒驿栈-5月满89减30（品20） | E5: 总部 | F5: 酒专营 | G5: 全国（剔除安徽、浙江） | H5: 酒驿栈 | J5: 满89减30（品20） | K5: 青岛啤酒畅饮券 | L5: 10000 | M5: 互斥 | N5: 75996666 | P5: 76128413【26年5月青岛啤酒共补】 | Q5: 青岛啤酒1 | R5: 4.21 | S5: 第一批 | T5: 已提报
A6: 单品牌券 | B6: 自配 | C6: 5.1-5.31 | D6: 区域下沉-青啤福建超市-5月满89减15 | E6: 福建营销 | F6: 超市 | G6: 福建 | H6: 超市 | J6: 满89减15 | K6: 青岛啤酒品牌券 | L6: 5000 | M6: 同享 | R6: 4.21 | S6: 第一批 | T6: 已提报
A7: 单品牌券 | B7: 自配 | C7: 5.1-5.31 | D7: 区域下沉-青啤福建超市-5月满125减30 | E7: 福建营销 | F7: 超市 | G7: 福建 | H7: 超市 | J7: 满125减30 | K7: 青岛啤酒品牌券 | L7: 5000 | M7: 同享 | R7: 4.21 | S7: 第一批 | T7: 已提报
A8: 单品牌券 | B8: 自配 | C8: 5.1-5.31 | D8: 区域下沉-青啤福建便利-5月满69减10 | E8: 福建营销 | F8: 便利 | G8: 福建 | H8: 便利 | J8: 满69减10 | K8: 青岛啤酒品牌券 | L8: 10000 | M8: 同享 | R8: 4.21 | S8: 第一批 | T8: 已提报
A9: 单品牌券 | B9: 自配 | C9: 5.1-5.31 | D9: 区域下沉-青啤福建便利-5月满99减20 | E9: 福建营销 | F9: 便利 | G9: 福建 | H9: 便利 | J9: 满99减20 | K9: 青岛啤酒品牌券 | L9: 10000 | M9: 同享 | R9: 4.21 | S9: 第一批 | T9: 已提报
A10: 单品牌券 | B10: 自配 | C10: 5.1-5.31 | D10: 区域下沉-青啤福建闪电仓-5月满69减10 | E10: 福建营销 | F10: 闪电仓 | G10: 福建 | H10: 闪电仓 | J10: 满69减10 | K10: 青岛啤酒品牌券 | L10: 15000 | M10: 同享 | R10: 4.21 | S10: 第一批 | T10: 已提报
A11: 单品牌券 | B11: 自配 | C11: 5.1-5.31 | D11: 区域下沉-青啤福建闪电仓-5月满99减20 | E11: 福建营销 | F11: 闪电仓 | G11: 福建 | H11: 闪电仓 | J11: 满99减20 | K11: 青岛啤酒品牌券 | L11: 15000 | M11: 同享 | R11: 4.21 | S11: 第一批 | T11: 已提报
A12: 单品牌券 | B12: 自配 | C12: 5.1-5.31 | D12: 区域下沉-青啤福建酒专营-5月满99减20 | E12: 福建营销 | F12: 酒专营 | G12: 福建 | H12: 酒专营 | J12: 满99减20 | K12: 青岛啤酒品牌券 | L12: 15000 | M12: 同享 | R12: 4.21 | S12: 第一批 | T12: 已提报
A13: 单品牌券 | B13: 自配 | C13: 5.1-5.31 | D13: 区域下沉-青啤福建酒专营-5月满125减30 | E13: 福建营销 | F13: 酒专营 | G13: 福建 | H13: 酒专营 | J13: 满125减30 | K13: 青岛啤酒品牌券 | L13: 15000 | M13: 同享 | R13: 4.21 | S13: 第一批 | T13: 已提报
A14: 单品牌券 | B14: 自配 | C14: 5.1-5.31 | D14: 区域下沉-青啤福建散店-5月满69减10 | E14: 福建营销 | F14: 散店 | G14: 福建 | H14: 散店 | J14: 满69减10 | K14: 青岛啤酒品牌券 | L14: 20000 | M14: 同享 | R14: 4.21 | S14: 第一批 | T14: 已提报
A15: 单品牌券 | B15: 自配 | C15: 5.1-5.31 | D15: 区域下沉-青啤福建散店-5月满99减20 | E15: 福建营销 | F15: 散店 | G15: 福建 | H15: 散店 | J15: 满99减20 | K15: 青岛啤酒品牌券 | L15: 20000 | M15: 同享 | R15: 4.21 | S15: 第一批 | T15: 已提报
A16: 单品牌券 | B16: 自配 | C16: 5.1-5.31 | D16: 区域下沉-青啤福建全渠道-5月满36减6 | E16: 福建营销 | F16: 全渠道 | G16: 福建 | H16: 全渠道 | J16: 满36减6 | K16: 青岛啤酒品牌券 | L16: 30000 | M16: 同享 | R16: 4.21 | S16: 第一批 | T16: 已提报
A17: 单品牌券 | B17: 自配 | C17: 5.1-5.31(每日18:00-06:00） | D17: 区域下沉-青啤海南全渠道夜间-5月满59减10 | E17: 海南省区 | F17: 全渠道 | G17: 海南 | H17: 全渠道（除散店） | J17: 满59减10 | K17: 青岛啤酒品牌券 | L17: 30000 | M17: 同享 | R17: 4.21 | S17: 第一批 | T17: 已提报
A18: 单品牌券 | B18: 自配 | C18: 5.1-5.31(每日18:00-06:00） | D18: 区域下沉-青啤海南全渠道夜间-5月满79减15 | E18: 海南省区 | F18: 全渠道 | G18: 海南 | H18: 全渠道（除散店） | J18: 满79减15 | K18: 青岛啤酒品牌券 | L18: 20000 | M18: 同享 | R18: 4.21 | S18: 第一批 | T18: 已提报
A19: 单品牌券 | B19: 三方混补 | C19: 5.1-5.7 | D19: 青啤北京酒专营-5月满69减20（品12） | E19: 北京销售 | F19: 酒专营 | G19: 北京、秦皇岛、唐山、张家口、承德 | H19: 酒专营 | J19: 满69减20（品12） | K19: 青岛啤酒畅饮券 | L19: 6000 | M19: 互斥 | N19: 76038096 | P19: 76128413【26年5月青岛啤酒共补】 | Q19: 青岛啤酒1 | R19: 4.21 | S19: 第一批 | T19: 已提报
A20: 单品牌券 | B20: 三方混补 | C20: 5.1-5.7 | D20: 青啤北京闪电仓-5月满69减20（品12） | E20: 北京销售 | F20: 闪电仓 | G20: 北京、秦皇岛、唐山、张家口、承德 | H20: 闪电仓（剔除小象超市、惠宜选、共橙超市、厉臣超市） | J20: 满69减20（品12） | K20: 青岛啤酒畅饮券 | L20: 6000 | M20: 互斥 | N20: 76045524 | P20: 76128413【26年5月青岛啤酒共补】 | Q20: 青岛啤酒-闪电仓 | R20: 4.21 | S20: 第一批 | T20: 已提报
A21: 单品牌券 | B21: 三方混补 | C21: 5.1-5.7 | D21: 青啤北京松鼠便利-5月满69减20（品12） | E21: 北京销售 | F21: 松鼠便利 | G21: 北京、秦皇岛、唐山、张家口、承德 | H21: 松鼠便利 | J21: 满69减20（品12） | K21: 青岛啤酒畅饮券 | L21: 6000 | M21: 互斥 | N21: 76008982 | P21: 76128413【26年5月青岛啤酒共补】 | Q21: 青岛啤酒2 | R21: 4.21 | S21: 第一批 | T21: 已提报
A22: 单品牌券 | B22: 自配 | C22: 5.1-5.7 | D22: 区域下沉-青啤北京全渠道-5月满99减20 | E22: 北京销售 | F22: 全渠道 | G22: 北京、秦皇岛、唐山、张家口、承德 | H22: 全渠道（剔除小象超市、惠宜选、共橙超市、厉臣超市） | J22: 满99减20 | K22: 青岛啤酒品牌券 | L22: 20000 | M22: 同享 | R22: 4.21 | S22: 第一批 | T22: 已提报
A23: 单品牌券 | B23: 三方混补 | C23: 5.6-5.31 | D23: 青啤北京酒专营-5月满59减20（品12）新 | E23: 北京销售 | F23: 酒专营 | G23: 北京、秦皇岛、唐山、张家口、承德 | H23: 酒专营 | J23: 满59减20（品12） | K23: 青岛啤酒畅饮券 | L23: 6000 | M23: 互斥 | N23: 76057203 | O23: 纯生产品剔除 | P23: 76128413【26年5月青岛啤酒共补】 | Q23: 青岛啤酒1 | R23: 4.21 | S23: 第一批 | T23: 没有品明细
A24: 单品牌券 | B24: 三方混补 | C24: 5.6-5.31 | D24: 青啤北京闪电仓-5月满59减20（品12）新 | E24: 北京销售 | F24: 闪电仓 | G24: 北京、秦皇岛、唐山、张家口、承德 | H24: 闪电仓（剔除小象超市、惠宜选、共橙超市、厉臣超市） | J24: 满59减20（品12） | K24: 青岛啤酒畅饮券 | L24: 6000 | M24: 互斥 | N24: 75997829 | O24: 纯生产品剔除 | P24: 76128413【26年5月青岛啤酒共补】 | Q24: 青岛啤酒-闪电仓 | R24: 4.21 | S24: 第一批 | T24: 没有品明细
A25: 单品牌券 | B25: 三方混补 | C25: 5.6-5.31 | D25: 青啤北京松鼠便利-5月满59减20（品12）新 | E25: 北京销售 | F25: 松鼠便利 | G25: 北京、秦皇岛、唐山、张家口、承德 | H25: 松鼠便利 | J25: 满59减20（品12） | K25: 青岛啤酒畅饮券 | L25: 6000 | M25: 互斥 | N25: 76001760 | O25: 纯生产品剔除 | P25: 76128413【26年5月青岛啤酒共补】 | Q25: 青岛啤酒2 | R25: 4.21 | S25: 第一批 | T25: 没有品明细
A26: 单品牌券 | B26: 自配 | C26: 5.1-5.31 | D26: 区域下沉-青啤北京全渠道-5月满49减4 | E26: 北京销售 | F26: 全渠道 | G26: 北京、秦皇岛、唐山、张家口、承德 | H26: 全渠道（剔除小象超市、歪马送酒、惠宜选、共橙超市、厉臣超市、大润发） | J26: 满49减4 | K26: 青岛啤酒品牌券 | L26: 20000 | M26: 同享 | R26: 4.21 | S26: 第一批 | T26: 已提报
A27: 单品牌券 | B27: 三方混补 | C27: 5.1-5.31 | D27: 青啤北京酒专营-5月满79减20（品14） | E27: 北京销售 | F27: 酒专营 | G27: 北京、秦皇岛、唐山、张家口、承德 | H27: 酒专营 | J27: 满79减20（品14） | K27: 青岛啤酒畅饮券 | L27: 6000 | M27: 互斥 | N27: 76130306 | P27: 76128413【26年5月青岛啤酒共补】 | Q27: 青岛啤酒1 | R27: 4.21 | S27: 第一批 | T27: 已提报
A28: 单品牌券 | B28: 三方混补 | C28: 5.1-5.31 | D28: 青啤北京闪电仓-5月满79减20（品14） | E28: 北京销售 | F28: 闪电仓 | G28: 北京、秦皇岛、唐山、张家口、承德 | H28: 闪电仓（剔除小象超市、惠宜选、共橙超市、厉臣超市） | J28: 满79减20（品14） | K28: 青岛啤酒畅饮券 | L28: 6000 | M28: 互斥 | N28: 76099140 | P28: 76128413【26年5月青岛啤酒共补】 | Q28: 青岛啤酒-闪电仓 | R28: 4.21 | S28: 第一批 | T28: 已提报
A29: 单品牌券 | B29: 三方混补 | C29: 5.1-5.31 | D29: 青啤北京松鼠便利-5月满79减20（品14） | E29: 北京销售 | F29: 松鼠便利 | G29: 北京、秦皇岛、唐山、张家口、承德 | H29: 松鼠便利 | J29: 满79减20（品14） | K29: 青岛啤酒畅饮券 | L29: 6000 | M29: 互斥 | N29: 76128487 | P29: 76128413【26年5月青岛啤酒共补】 | Q29: 青岛啤酒2 | R29: 4.21 | S29: 第一批 | T29: 已提报
A30: 单品牌券 | B30: 三方混补 | C30: 5.1-5.31 | D30: 青啤北京酒专营-5月满99减50（品25） | E30: 北京销售 | F30: 酒专营 | G30: 北京、秦皇岛、唐山、张家口、承德 | H30: 酒专营 | J30: 满99减50（品25） | K30: 青岛啤酒畅饮券 | L30: 6000 | M30: 互斥 | N30: 76129393 | P30: 76128413【26年5月青岛啤酒共补】 | Q30: 青岛啤酒1 | R30: 4.21 | S30: 第一批 | T30: 已提报
A31: 单品牌券 | B31: 三方混补 | C31: 5.1-5.31 | D31: 青啤北京闪电仓-5月满99减50（品25） | E31: 北京销售 | F31: 闪电仓 | G31: 北京、秦皇岛、唐山、张家口、承德 | H31: 闪电仓（剔除小象超市、惠宜选、共橙超市、厉臣超市） | J31: 满99减50（品25） | K31: 青岛啤酒畅饮券 | L31: 6000 | M31: 互斥 | N31: 76100033 | P31: 76128413【26年5月青岛啤酒共补】 | Q31: 青岛啤酒-闪电仓 | R31: 4.21 | S31: 第一批 | T31: 已提报
A32: 单品牌券 | B32: 三方混补 | C32: 5.1-5.31 | D32: 青啤北京松鼠便利-5月满99减50（品25） | E32: 北京销售 | F32: 松鼠便利 | G32: 北京、秦皇岛、唐山、张家口、承德 | H32: 松鼠便利 | J32: 满99减50（品25） | K32: 青岛啤酒畅饮券 | L32: 6000 | M32: 互斥 | N32: 76042236 | P32: 76128413【26年5月青岛啤酒共补】 | Q32: 青岛啤酒2 | R32: 4.21 | S32: 第一批 | T32: 已提报
A33: 单品牌券 | B33: 三方混补 | C33: 5.1-5.31(每日18:00-02:00） | D33: 青啤北京酒专营-5月满25减10（品7） | E33: 北京销售 | F33: 酒专营 | G33: 北京、秦皇岛、唐山、张家口、承德 | H33: 酒专营 | J33: 满25减10（品7） | K33: 青岛啤酒畅饮券 | L33: 6000 | M33: 互斥 | N33: 75999612 | P33: 76128413【26年5月青岛啤酒共补】 | Q33: 青岛啤酒1 | R33: 4.21 | S33: 第一批 | T33: 已提报
A34: 单品牌券 | B34: 三方混补 | C34: 5.1-5.31(每日18:00-02:00） | D34: 青啤北京闪电仓-5月满25减10（品7） | E34: 北京销售 | F34: 闪电仓 | G34: 北京、秦皇岛、唐山、张家口、承德 | H34: 闪电仓（剔除小象超市、惠宜选、共橙超市、厉臣超市） | J34: 满25减10（品7） | K34: 青岛啤酒畅饮券 | L34: 6000 | M34: 互斥 | N34: 75996866 | P34: 76128413【26年5月青岛啤酒共补】 | Q34: 青岛啤酒-闪电仓 | R34: 4.21 | S34: 第一批 | T34: 已提报
A35: 单品牌券 | B35: 三方混补 | C35: 5.1-5.31(每日18:00-02:00） | D35: 青啤北京松鼠便利-5月满25减10（品7） | E35: 北京销售 | F35: 松鼠便利 | G35: 北京、秦皇岛、唐山、张家口、承德 | H35: 松鼠便利 | J35: 满25减10（品7） | K35: 青岛啤酒畅饮券 | L35: 6000 | M35: 互斥 | N35: 76063140 | P35: 76128413【26年5月青岛啤酒共补】 | Q35: 青岛啤酒2 | R35: 4.21 | S35: 第一批 | T35: 已提报
A36: 单品牌券 | B36: 自配 | C36: 5.1-5.31 | D36: 区域下沉-青啤北京闪电仓-5月满15减3 | E36: 北京销售 | F36: 闪电仓 | G36: 北京、秦皇岛、唐山、张家口、承德 | H36: 闪电仓（剔除小象超市、惠宜选、共橙超市、厉臣超市） | J36: 满15减3 | K36: 青岛啤酒品牌券 | L36: 20000 | M36: 同享 | R36: 4.21 | S36: 第一批 | T36: 已提报
A37: 单品牌券 | B37: 三方混补 | C37: 5.1-5.31 | D37: 青啤北京酒专营-5月满99减30（品15） | E37: 北京销售 | F37: 酒专营 | G37: 北京、秦皇岛、唐山、张家口、承德 | H37: 酒专营（剔除歪马送酒） | J37: 满99减30（品15） | K37: 青岛啤酒畅饮券 | L37: 20000 | M37: 互斥 | N37: 76016509 | P37: 76128413【26年5月青岛啤酒共补】 | Q37: 青岛啤酒1 | R37: 4.21 | S37: 第一批 | T37: 已提报
A38: 单品牌券 | B38: 自配 | C38: 5月每周五六日 | D38: 区域下沉-青啤黑龙江全渠道周末-5月满69减10 | E38: 黑龙江营销 | F38: 全渠道 | G38: 黑龙江 | H38: 全渠道 | J38: 满69减10 | K38: 青岛啤酒品牌券 | L38: 60000 | M38: 同享 | R38: 4.21 | S38: 第一批 | T38: 已提报
A39: 单品牌券 | B39: 自配 | C39: 5月每周五六日 | D39: 区域下沉-青啤黑龙江全渠道周末-5月满69减20 | E39: 黑龙江营销 | F39: 全渠道 | G39: 黑龙江 | H39: 全渠道 | J39: 满69减20 | K39: 青岛啤酒品牌券 | L39: 80000 | M39: 同享 | R39: 4.21 | S39: 第一批 | T39: 已提报
A40: 单品牌券 | B40: 自配 | C40: 5月每周五六日 | D40: 区域下沉-青啤黑龙江全渠道周末-5月满120减50 | E40: 黑龙江营销 | F40: 全渠道 | G40: 黑龙江 | H40: 全渠道 | J40: 满120减50 | K40: 青岛啤酒品牌券 | L40: 20000 | M40: 同享 | R40: 4.21 | S40: 第一批 | T40: 已提报
...

Sheet 选品详情
A1: 品牌商名称 | B1: 子品牌 | C1: 机制类型 | D1: 城市 | E1: 渠道 | F1: 活动名称（即后台自建券的活动名称） | G1: 同享/专享 | H1: 优惠力度 | I1: 活动开始时间 | J1: 活动结束时间 | K1: UPC条形码 | L1: 产品名称 | M1: 零售价
A2: 青岛啤酒 | B2: 青岛啤酒 | C2: =_xlfn.XLOOKUP(F2,'5月全部'!D:D,'5月全部'!A:A,0,1) -> 单品牌券 | D2: =_xlfn.XLOOKUP(F2,'5月全部'!D:D,'5月全部'!G:G,0,1) -> 全国 | E2: =_xlfn.XLOOKUP(F2,'5月全部'!D:D,'5月全部'!F:F,0,1) -> 闪电仓 | F2: 总-青啤全国快送熊-5月满59减20（品12） | G2: =_xlfn.XLOOKUP(F2,'5月全部'!D:D,'5月全部'!M:M,0,1) -> 互斥 | H2: =_xlfn.XLOOKUP(F2,'5月全部'!D:D,'5月全部'!J:J,0,1) -> 满59减20（品12） | I2: 46143 | J2: 46173 | K2: 6901035629478 | L2: 青岛啤酒夜猫子9度355ml/瓶
A3: 青岛啤酒 | B3: 青岛啤酒 | C3: =_xlfn.XLOOKUP(F3,'5月全部'!D:D,'5月全部'!A:A,0,1) -> 单品牌券 | D3: =_xlfn.XLOOKUP(F3,'5月全部'!D:D,'5月全部'!G:G,0,1) -> 全国 | E3: =_xlfn.XLOOKUP(F3,'5月全部'!D:D,'5月全部'!F:F,0,1) -> 闪电仓 | F3: 总-青啤全国快送熊-5月满59减20（品12） | G3: =_xlfn.XLOOKUP(F3,'5月全部'!D:D,'5月全部'!M:M,0,1) -> 互斥 | H3: =_xlfn.XLOOKUP(F3,'5月全部'!D:D,'5月全部'!J:J,0,1) -> 满59减20（品12） | I3: 46143 | J3: 46173 | K3: 6920833900558 | L3: 青岛啤酒夜猫子联名版9度355ml瓶*3/组
A4: 青岛啤酒 | B4: 青岛啤酒 | C4: =_xlfn.XLOOKUP(F4,'5月全部'!D:D,'5月全部'!A:A,0,1) -> 单品牌券 | D4: =_xlfn.XLOOKUP(F4,'5月全部'!D:D,'5月全部'!G:G,0,1) -> 全国 | E4: =_xlfn.XLOOKUP(F4,'5月全部'!D:D,'5月全部'!F:F,0,1) -> 闪电仓 | F4: 总-青啤全国快送熊-5月满59减20（品12） | G4: =_xlfn.XLOOKUP(F4,'5月全部'!D:D,'5月全部'!M:M,0,1) -> 互斥 | H4: =_xlfn.XLOOKUP(F4,'5月全部'!D:D,'5月全部'!J:J,0,1) -> 满59减20（品12） | I4: 46143 | J4: 46173 | K4: 6920833900527 | L4: 青岛啤酒夜猫子联名版9度355ml瓶*6/组
A5: 青岛啤酒 | B5: 青岛啤酒 | C5: =_xlfn.XLOOKUP(F5,'5月全部'!D:D,'5月全部'!A:A,0,1) -> 单品牌券 | D5: =_xlfn.XLOOKUP(F5,'5月全部'!D:D,'5月全部'!G:G,0,1) -> 全国 | E5: =_xlfn.XLOOKUP(F5,'5月全部'!D:D,'5月全部'!F:F,0,1) -> 闪电仓 | F5: 总-青啤全国快送熊-5月满59减20（品12） | G5: =_xlfn.XLOOKUP(F5,'5月全部'!D:D,'5月全部'!M:M,0,1) -> 互斥 | H5: =_xlfn.XLOOKUP(F5,'5月全部'!D:D,'5月全部'!J:J,0,1) -> 满59减20（品12） | I5: 46143 | J5: 46173 | K5: 6901035628686 | L5: 青岛啤酒轻干8度500ml/罐
A6: 青岛啤酒 | B6: 青岛啤酒 | C6: =_xlfn.XLOOKUP(F6,'5月全部'!D:D,'5月全部'!A:A,0,1) -> 单品牌券 | D6: =_xlfn.XLOOKUP(F6,'5月全部'!D:D,'5月全部'!G:G,0,1) -> 全国 | E6: =_xlfn.XLOOKUP(F6,'5月全部'!D:D,'5月全部'!F:F,0,1) -> 闪电仓 | F6: 总-青啤全国快送熊-5月满59减20（品12） | G6: =_xlfn.XLOOKUP(F6,'5月全部'!D:D,'5月全部'!M:M,0,1) -> 互斥 | H6: =_xlfn.XLOOKUP(F6,'5月全部'!D:D,'5月全部'!J:J,0,1) -> 满59减20（品12） | I6: 46143 | J6: 46173 | K6: 6901035628655 | L6: 青岛啤酒轻干8度330ml/罐
A7: 青岛啤酒 | B7: 青岛啤酒 | C7: =_xlfn.XLOOKUP(F7,'5月全部'!D:D,'5月全部'!A:A,0,1) -> 单品牌券 | D7: =_xlfn.XLOOKUP(F7,'5月全部'!D:D,'5月全部'!G:G,0,1) -> 全国 | E7: =_xlfn.XLOOKUP(F7,'5月全部'!D:D,'5月全部'!F:F,0,1) -> 闪电仓 | F7: 总-青啤全国快送熊-5月满59减20（品12） | G7: =_xlfn.XLOOKUP(F7,'5月全部'!D:D,'5月全部'!M:M,0,1) -> 互斥 | H7: =_xlfn.XLOOKUP(F7,'5月全部'!D:D,'5月全部'!J:J,0,1) -> 满59减20（品12） | I7: 46143 | J7: 46173 | K7: 6901035628662 | L7: 青岛啤酒轻干8度330ml*6罐/组
A8: 青岛啤酒 | B8: 青岛啤酒 | C8: =_xlfn.XLOOKUP(F8,'5月全部'!D:D,'5月全部'!A:A,0,1) -> 单品牌券 | D8: =_xlfn.XLOOKUP(F8,'5月全部'!D:D,'5月全部'!G:G,0,1) -> 全国 | E8: =_xlfn.XLOOKUP(F8,'5月全部'!D:D,'5月全部'!F:F,0,1) -> 闪电仓 | F8: 总-青啤全国快送熊-5月满59减20（品12） | G8: =_xlfn.XLOOKUP(F8,'5月全部'!D:D,'5月全部'!M:M,0,1) -> 互斥 | H8: =_xlfn.XLOOKUP(F8,'5月全部'!D:D,'5月全部'!J:J,0,1) -> 满59减20（品12） | I8: 46143 | J8: 46173 | K8: 6901035606325 | L8: 青岛啤酒纯生瓶600ml*3/组
A9: 青岛啤酒 | B9: 青岛啤酒 | C9: =_xlfn.XLOOKUP(F9,'5月全部'!D:D,'5月全部'!A:A,0,1) -> 单品牌券 | D9: =_xlfn.XLOOKUP(F9,'5月全部'!D:D,'5月全部'!G:G,0,1) -> 全国 | E9: =_xlfn.XLOOKUP(F9,'5月全部'!D:D,'5月全部'!F:F,0,1) -> 闪电仓 | F9: 总-青啤全国快送熊-5月满59减20（品12） | G9: =_xlfn.XLOOKUP(F9,'5月全部'!D:D,'5月全部'!M:M,0,1) -> 互斥 | H9: =_xlfn.XLOOKUP(F9,'5月全部'!D:D,'5月全部'!J:J,0,1) -> 满59减20（品12） | I9: 46143 | J9: 46173 | K9: 6901035602242 | L9: 青岛啤酒纯生罐330ml*6/组
A10: 青岛啤酒 | B10: 青岛啤酒 | C10: =_xlfn.XLOOKUP(F10,'5月全部'!D:D,'5月全部'!A:A,0,1) -> 单品牌券 | D10: =_xlfn.XLOOKUP(F10,'5月全部'!D:D,'5月全部'!G:G,0,1) -> 全国 | E10: =_xlfn.XLOOKUP(F10,'5月全部'!D:D,'5月全部'!F:F,0,1) -> 闪电仓 | F10: 总-青啤全国快送熊-5月满59减20（品12） | G10: =_xlfn.XLOOKUP(F10,'5月全部'!D:D,'5月全部'!M:M,0,1) -> 互斥 | H10: =_xlfn.XLOOKUP(F10,'5月全部'!D:D,'5月全部'!J:J,0,1) -> 满59减20（品12） | I10: 46143 | J10: 46173 | K10: 6901035612678 | L10: 青岛啤酒纯生罐330ml*6/组
A11: 青岛啤酒 | B11: 青岛啤酒 | C11: =_xlfn.XLOOKUP(F11,'5月全部'!D:D,'5月全部'!A:A,0,1) -> 单品牌券 | D11: =_xlfn.XLOOKUP(F11,'5月全部'!D:D,'5月全部'!G:G,0,1) -> 全国 | E11: =_xlfn.XLOOKUP(F11,'5月全部'!D:D,'5月全部'!F:F,0,1) -> 闪电仓 | F11: 总-青啤全国快送熊-5月满59减20（品12） | G11: =_xlfn.XLOOKUP(F11,'5月全部'!D:D,'5月全部'!M:M,0,1) -> 互斥 | H11: =_xlfn.XLOOKUP(F11,'5月全部'!D:D,'5月全部'!J:J,0,1) -> 满59减20（品12） | I11: 46143 | J11: 46173 | K11: 6901035621083 | L11: 青岛啤酒纯生罐500ml*3/组
A12: 青岛啤酒 | B12: 青岛啤酒 | C12: =_xlfn.XLOOKUP(F12,'5月全部'!D:D,'5月全部'!A:A,0,1) -> 单品牌券 | D12: =_xlfn.XLOOKUP(F12,'5月全部'!D:D,'5月全部'!G:G,0,1) -> 全国 | E12: =_xlfn.XLOOKUP(F12,'5月全部'!D:D,'5月全部'!F:F,0,1) -> 闪电仓 | F12: 总-青啤全国快送熊-5月满59减20（品12） | G12: =_xlfn.XLOOKUP(F12,'5月全部'!D:D,'5月全部'!M:M,0,1) -> 互斥 | H12: =_xlfn.XLOOKUP(F12,'5月全部'!D:D,'5月全部'!J:J,0,1) -> 满59减20（品12） | I12: 46143 | J12: 46173 | K12: 6901035612203 | L12: 青岛啤酒纯生罐500ml*4/组
A13: 青岛啤酒 | B13: 青岛啤酒 | C13: =_xlfn.XLOOKUP(F13,'5月全部'!D:D,'5月全部'!A:A,0,1) -> 单品牌券 | D13: =_xlfn.XLOOKUP(F13,'5月全部'!D:D,'5月全部'!G:G,0,1) -> 全国 | E13: =_xlfn.XLOOKUP(F13,'5月全部'!D:D,'5月全部'!F:F,0,1) -> 闪电仓 | F13: 总-青啤全国快送熊-5月满59减20（品12） | G13: =_xlfn.XLOOKUP(F13,'5月全部'!D:D,'5月全部'!M:M,0,1) -> 互斥 | H13: =_xlfn.XLOOKUP(F13,'5月全部'!D:D,'5月全部'!J:J,0,1) -> 满59减20（品12） | I13: 46143 | J13: 46173 | K13: 6901035621151 | L13: 青岛啤酒纯生罐500ml*6/组
... A1168: 青岛啤酒 | B1168: 青岛啤酒 | C1168: =_xlfn.XLOOKUP(F1168,'5月全部'!D:D,'5月全部'!A:A,0,1) -> 单品牌券 | D1168: =_xlfn.XLOOKUP(F1168,'5月全部'!D:D,'5月全部'!G:G,0,1) -> 北京、秦皇岛、唐山、张家口、承德 | E1168: =_xlfn.XLOOKUP(F1168,'5月全部'!D:D,'5月全部'!F:F,0,1) -> 酒专营 | F1168: 青啤北京酒专营-5月满99减30（品15） | G1168: =_xlfn.XLOOKUP(F1168,'5月全部'!D:D,'5月全部'!M:M,0,1) -> 互斥 | H1168: =_xlfn.XLOOKUP(F1168,'5月全部'!D:D,'5月全部'!J:J,0,1) -> 满99减30（品15） | I1168: 46143 | J1168: 46173 | K1168: 6901035297776 | L1168: 青岛啤酒A3系列10.7度500ml*12罐/箱
A1169: 青岛啤酒 | B1169: 青岛啤酒 | C1169: =_xlfn.XLOOKUP(F1169,'5月全部'!D:D,'5月全部'!A:A,0,1) -> 单品牌券 | D1169: =_xlfn.XLOOKUP(F1169,'5月全部'!D:D,'5月全部'!G:G,0,1) -> 黑龙江 | E1169: =_xlfn.XLOOKUP(F1169,'5月全部'!D:D,'5月全部'!F:F,0,1) -> 全渠道 | F1169: 区域下沉-青啤黑龙江全渠道周末-5月满69减10 | G1169: =_xlfn.XLOOKUP(F1169,'5月全部'!D:D,'5月全部'!M:M,0,1) -> 同享 | H1169: =_xlfn.XLOOKUP(F1169,'5月全部'!D:D,'5月全部'!J:J,0,1) -> 满69减10 | I1169: 5月每周五六日 | J1169: 5月每周五六日 | K1169: 6901035630030 | L1169: 青岛啤酒樱花白啤罐500ml*3*4/箱
A1170: 青岛啤酒 | B1170: 青岛啤酒 | C1170: =_xlfn.XLOOKUP(F1170,'5月全部'!D:D,'5月全部'!A:A,0,1) -> 单品牌券 | D1170: =_xlfn.XLOOKUP(F1170,'5月全部'!D:D,'5月全部'!G:G,0,1) -> 黑龙江 | E1170: =_xlfn.XLOOKUP(F1170,'5月全部'!D:D,'5月全部'!F:F,0,1) -> 全渠道 | F1170: 区域下沉-青啤黑龙江全渠道周末-5月满69减10 | G1170: =_xlfn.XLOOKUP(F1170,'5月全部'!D:D,'5月全部'!M:M,0,1) -> 同享 | H1170: =_xlfn.XLOOKUP(F1170,'5月全部'!D:D,'5月全部'!J:J,0,1) -> 满69减10 | I1170: 5月每周五六日 | J1170: 5月每周五六日 | K1170: 6901035610209 | L1170: 青岛啤酒小罐330ml*6/组
A1171: 青岛啤酒 | B1171: 青岛啤酒 | C1171: =_xlfn.XLOOKUP(F1171,'5月全部'!D:D,'5月全部'!A:A,0,1) -> 单品牌券 | D1171: =_xlfn.XLOOKUP(F1171,'5月全部'!D:D,'5月全部'!G:G,0,1) -> 黑龙江 | E1171: =_xlfn.XLOOKUP(F1171,'5月全部'!D:D,'5月全部'!F:F,0,1) -> 全渠道 | F1171: 区域下沉-青啤黑龙江全渠道周末-5月满69减10 | G1171: =_xlfn.XLOOKUP(F1171,'5月全部'!D:D,'5月全部'!M:M,0,1) -> 同享 | H1171: =_xlfn.XLOOKUP(F1171,'5月全部'!D:D,'5月全部'!J:J,0,1) -> 满69减10 | I1171: 5月每周五六日 | J1171: 5月每周五六日 | K1171: 6901035605892 | L1171: 青岛啤酒10度经典罐啤330ml*24/箱
A1172: 青岛啤酒 | B1172: 青岛啤酒 | C1172: =_xlfn.XLOOKUP(F1172,'5月全部'!D:D,'5月全部'!A:A,0,1) -> 单品牌券 | D1172: =_xlfn.XLOOKUP(F1172,'5月全部'!D:D,'5月全部'!G:G,0,1) -> 黑龙江 | E1172: =_xlfn.XLOOKUP(F1172,'5月全部'!D:D,'5月全部'!F:F,0,1) -> 全渠道 | F1172: 区域下沉-青啤黑龙江全渠道周末-5月满69减10 | G1172: =_xlfn.XLOOKUP(F1172,'5月全部'!D:D,'5月全部'!M:M,0,1) -> 同享 | H1172: =_xlfn.XLOOKUP(F1172,'5月全部'!D:D,'5月全部'!J:J,0,1) -> 满69减10 | I1172: 5月每周五六日 | J1172: 5月每周五六日 | K1172: 6901035609722 | L1172: 青岛啤酒11度经典罐330ml*12/箱
A1173: 青岛啤酒 | B1173: 青岛啤酒 | C1173: =_xlfn.XLOOKUP(F1173,'5月全部'!D:D,'5月全部'!A:A,0,1) -> 单品牌券 | D1173: =_xlfn.XLOOKUP(F1173,'5月全部'!D:D,'5月全部'!G:G,0,1) -> 黑龙江 | E1173: =_xlfn.XLOOKUP(F1173,'5月全部'!D:D,'5月全部'!F:F,0,1) -> 全渠道 | F1173: 区域下沉-青啤黑龙江全渠道周末-5月满69减10 | G1173: =_xlfn.XLOOKUP(F1173,'5月全部'!D:D,'5月全部'!M:M,0,1) -> 同享 | H1173: =_xlfn.XLOOKUP(F1173,'5月全部'!D:D,'5月全部'!J:J,0,1) -> 满69减10 | I1173: 5月每周五六日 | J1173: 5月每周五六日 | K1173: 6901035608602 | L1173: 青岛啤酒11度经典罐啤33ml*24/箱
A1174: 青岛啤酒 | B1174: 青岛啤酒 | C1174: =_xlfn.XLOOKUP(F1174,'5月全部'!D:D,'5月全部'!A:A,0,1) -> 单品牌券 | D1174: =_xlfn.XLOOKUP(F1174,'5月全部'!D:D,'5月全部'!G:G,0,1) -> 黑龙江 | E1174: =_xlfn.XLOOKUP(F1174,'5月全部'!D:D,'5月全部'!F:F,0,1) -> 全渠道 | F1174: 区域下沉-青啤黑龙江全渠道周末-5月满69减10 | G1174: =_xlfn.XLOOKUP(F1174,'5月全部'!D:D,'5月全部'!M:M,0,1) -> 同享 | H1174: =_xlfn.XLOOKUP(F1174,'5月全部'!D:D,'5月全部'!J:J,0,1) -> 满69减10 | I1174: 5月每周五六日 | J1174: 5月每周五六日 | K1174: 6901035609272 | L1174: 青岛啤酒经典11度330*24罐啤
A1175: 青岛啤酒 | B1175: 青岛啤酒 | C1175: =_xlfn.XLOOKUP(F1175,'5月全部'!D:D,'5月全部'!A:A,0,1) -> 单品牌券 | D1175: =_xlfn.XLOOKUP(F1175,'5月全部'!D:D,'5月全部'!G:G,0,1) -> 黑龙江 | E1175: =_xlfn.XLOOKUP(F1175,'5月全部'!D:D,'5月全部'!F:F,0,1) -> 全渠道 | F1175: 区域下沉-青啤黑龙江全渠道周末-5月满69减10 | G1175: =_xlfn.XLOOKUP(F1175,'5月全部'!D:D,'5月全部'!M:M,0,1) -> 同享 | H1175: =_xlfn.XLOOKUP(F1175,'5月全部'!D:D,'5月全部'!J:J,0,1) -> 满69减10 | I1175: 5月每周五六日 | J1175: 5月每周五六日 | K1175: 6901035604284 | L1175: 青岛啤酒经典10度500ml/瓶
A1176: 青岛啤酒 | B1176: 青岛啤酒 | C1176: =_xlfn.XLOOKUP(F1176,'5月全部'!D:D,'5月全部'!A:A,0,1) -> 单品牌券 | D1176: =_xlfn.XLOOKUP(F1176,'5月全部'!D:D,'5月全部'!G:G,0,1) -> 黑龙江 | E1176: =_xlfn.XLOOKUP(F1176,'5月全部'!D:D,'5月全部'!F:F,0,1) -> 全渠道 | F1176: 区域下沉-青啤黑龙江全渠道周末-5月满69减10 | G1176: =_xlfn.XLOOKUP(F1176,'5月全部'!D:D,'5月全部'!M:M,0,1) -> 同享 | H1176: =_xlfn.XLOOKUP(F1176,'5月全部'!D:D,'5月全部'!J:J,0,1) -> 满69减10 | I1176: 5月每周五六日 | J1176: 5月每周五六日 | K1176: 6923740100059 | L1176: 青岛啤酒经典10度600ml/瓶
A1177: 青岛啤酒 | B1177: 青岛啤酒 | C1177: =_xlfn.XLOOKUP(F1177,'5月全部'!D:D,'5月全部'!A:A,0,1) -> 单品牌券 | D1177: =_xlfn.XLOOKUP(F1177,'5月全部'!D:D,'5月全部'!G:G,0,1) -> 黑龙江 | E1177: =_xlfn.XLOOKUP(F1177,'5月全部'!D:D,'5月全部'!F:F,0,1) -> 全渠道 | F1177: 区域下沉-青啤黑龙江全渠道周末-5月满69减10 | G1177: =_xlfn.XLOOKUP(F1177,'5月全部'!D:D,'5月全部'!M:M,0,1) -> 同享 | H1177: =_xlfn.XLOOKUP(F1177,'5月全部'!D:D,'5月全部'!J:J,0,1) -> 满69减10 | I1177: 5月每周五六日 | J1177: 5月每周五六日 | K1177: 690103560220 | L1177: 青岛啤酒 11°P经典啤酒 330ml*24听/箱
A1178: 青岛啤酒 | B1178: 青岛啤酒 | C1178: =_xlfn.XLOOKUP(F1178,'5月全部'!D:D,'5月全部'!A:A,0,1) -> 单品牌券 | D1178: =_xlfn.XLOOKUP(F1178,'5月全部'!D:D,'5月全部'!G:G,0,1) -> 黑龙江 | E1178: =_xlfn.XLOOKUP(F1178,'5月全部'!D:D,'5月全部'!F:F,0,1) -> 全渠道 | F1178: 区域下沉-青啤黑龙江全渠道周末-5月满69减10 | G1178: =_xlfn.XLOOKUP(F1178,'5月全部'!D:D,'5月全部'!M:M,0,1) -> 同享 | H1178: =_xlfn.XLOOKUP(F1178,'5月全部'!D:D,'5月全部'!J:J,0,1) -> 满69减10 | I1178: 5月每周五六日 | J1178: 5月每周五六日 | K1178: 6901035602204 | L1178: 青岛啤酒经典罐330ml*6*4/箱
A1179: 青岛啤酒 | B1179: 青岛啤酒 | C1179: =_xlfn.XLOOKUP(F1179,'5月全部'!D:D,'5月全部'!A:A,0,1) -> 单品牌券 | D1179: =_xlfn.XLOOKUP(F1179,'5月全部'!D:D,'5月全部'!G:G,0,1) -> 黑龙江 | E1179: =_xlfn.XLOOKUP(F1179,'5月全部'!D:D,'5月全部'!F:F,0,1) -> 全渠道 | F1179: 区域下沉-青啤黑龙江全渠道周末-5月满69减10 | G1179: =_xlfn.XLOOKUP(F1179,'5月全部'!D:D,'5月全部'!M:M,0,1) -> 同享 | H1179: =_xlfn.XLOOKUP(F1179,'5月全部'!D:D,'5月全部'!J:J,0,1) -> 满69减10 | I1179: 5月每周五六日 | J1179: 5月每周五六日 | K1179: 6901035612173 | L1179: 青岛啤酒10度优质罐啤500ml*4*6/箱
A1180: 青岛啤酒 | B1180: 青岛啤酒 | C1180: =_xlfn.XLOOKUP(F1180,'5月全部'!D:D,'5月全部'!A:A,0,1) -> 单品牌券 | D1180: =_xlfn.XLOOKUP(F1180,'5月全部'!D:D,'5月全部'!G:G,0,1) -> 黑龙江 | E1180: =_xlfn.XLOOKUP(F1180,'5月全部'!D:D,'5月全部'!F:F,0,1) -> 全渠道 | F1180: 区域下沉-青啤黑龙江全渠道周末-5月满69减10 | G1180: =_xlfn.XLOOKUP(F1180,'5月全部'!D:D,'5月全部'!M:M,0,1) -> 同享 | H1180: =_xlfn.XLOOKUP(F1180,'5月全部'!D:D,'5月全部'!J:J,0,1) -> 满69减10 | I1180: 5月每周五六日 | J1180: 5月每周五六日 | K1180: 6901035612128 | L1180: 青岛啤酒10度优质箱啤600ml*6/箱
... A2578: 青岛啤酒 | B2578: 青岛啤酒 | C2578: =_xlfn.XLOOKUP(F2578,'5月全部'!D:D,'5月全部'!A:A,0,1) -> 单品牌券 | D2578: =_xlfn.XLOOKUP(F2578,'5月全部'!D:D,'5月全部'!G:G,0,1) -> 黑龙江 | E2578: =_xlfn.XLOOKUP(F2578,'5月全部'!D:D,'5月全部'!F:F,0,1) -> 便利 | F2578: 青啤黑龙江便利周末-5月第一件9块9 | G2578: =_xlfn.XLOOKUP(F2578,'5月全部'!D:D,'5月全部'!M:M,0,1) -> 互斥 | H2578: =_xlfn.XLOOKUP(F2578,'5月全部'!D:D,'5月全部'!J:J,0,1) -> 第一件9块9 | I2578: 5月每周五六日 | J2578: 5月每周五六日 | K2578: 6901035629317 | L2578: 青岛啤酒经典生啤10度1L马口铁桶啤
A2579: 青岛啤酒 | B2579: 青岛啤酒 | C2579: =_xlfn.XLOOKUP(F2579,'5月全部'!D:D,'5月全部'!A:A,0,1) -> 单品牌券 | D2579: =_xlfn.XLOOKUP(F2579,'5月全部'!D:D,'5月全部'!G:G,0,1) -> 黑龙江 | E2579: =_xlfn.XLOOKUP(F2579,'5月全部'!D:D,'5月全部'!F:F,0,1) -> 便利 | F2579: 青啤黑龙江便利-5月满69减40（品20） | G2579: =_xlfn.XLOOKUP(F2579,'5月全部'!D:D,'5月全部'!M:M,0,1) -> 互斥 | H2579: =_xlfn.XLOOKUP(F2579,'5月全部'!D:D,'5月全部'!J:J,0,1) -> 满69减40（品20） | I2579: 46160 | J2579: 46160 | K2579: 6923740105085 | L2579: 青岛啤酒听装330ml/听
A2580: 青岛啤酒 | B2580: 青岛啤酒 | C2580: =_xlfn.XLOOKUP(F2580,'5月全部'!D:D,'5月全部'!A:A,0,1) -> 单品牌券 | D2580: =_xlfn.XLOOKUP(F2580,'5月全部'!D:D,'5月全部'!G:G,0,1) -> 黑龙江 | E2580: =_xlfn.XLOOKUP(F2580,'5月全部'!D:D,'5月全部'!F:F,0,1) -> 便利 | F2580: 青啤黑龙江便利-5月满69减40（品20） | G2580: =_xlfn.XLOOKUP(F2580,'5月全部'!D:D,'5月全部'!M:M,0,1) -> 互斥 | H2580: =_xlfn.XLOOKUP(F2580,'5月全部'!D:D,'5月全部'!J:J,0,1) -> 满69减40（品20） | I2580: 46160 | J2580: 46160 | K2580: 6901035610209 | L2580: 青岛啤酒小罐330ml*6/组
A2581: 青岛啤酒 | B2581: 青岛啤酒 | C2581: =_xlfn.XLOOKUP(F2581,'5月全部'!D:D,'5月全部'!A:A,0,1) -> 单品牌券 | D2581: =_xlfn.XLOOKUP(F2581,'5月全部'!D:D,'5月全部'!G:G,0,1) -> 黑龙江 | E2581: =_xlfn.XLOOKUP(F2581,'5月全部'!D:D,'5月全部'!F:F,0,1) -> 便利 | F2581: 青啤黑龙江便利-5月满69减40（品20） | G2581: =_xlfn.XLOOKUP(F2581,'5月全部'!D:D,'5月全部'!M:M,0,1) -> 互斥 | H2581: =_xlfn.XLOOKUP(F2581,'5月全部'!D:D,'5月全部'!J:J,0,1) -> 满69减40（品20） | I2581: 46160 | J2581: 46160 | K2581: 6901035605892 | L2581: 青岛啤酒10度经典罐啤330ml*24/箱
A2582: 青岛啤酒 | B2582: 青岛啤酒 | C2582: =_xlfn.XLOOKUP(F2582,'5月全部'!D:D,'5月全部'!A:A,0,1) -> 单品牌券 | D2582: =_xlfn.XLOOKUP(F2582,'5月全部'!D:D,'5月全部'!G:G,0,1) -> 黑龙江 | E2582: =_xlfn.XLOOKUP(F2582,'5月全部'!D:D,'5月全部'!F:F,0,1) -> 便利 | F2582: 青啤黑龙江便利-5月满69减40（品20） | G2582: =_xlfn.XLOOKUP(F2582,'5月全部'!D:D,'5月全部'!M:M,0,1) -> 互斥 | H2582: =_xlfn.XLOOKUP(F2582,'5月全部'!D:D,'5月全部'!J:J,0,1) -> 满69减40（品20） | I2582: 46160 | J2582: 46160 | K2582: 6901035609722 | L2582: 青岛啤酒11度经典罐330ml*12/箱
A2583: 青岛啤酒 | B2583: 青岛啤酒 | C2583: =_xlfn.XLOOKUP(F2583,'5月全部'!D:D,'5月全部'!A:A,0,1) -> 单品牌券 | D2583: =_xlfn.XLOOKUP(F2583,'5月全部'!D:D,'5月全部'!G:G,0,1) -> 黑龙江 | E2583: =_xlfn.XLOOKUP(F2583,'5月全部'!D:D,'5月全部'!F:F,0,1) -> 便利 | F2583: 青啤黑龙江便利-5月满69减40（品20） | G2583: =_xlfn.XLOOKUP(F2583,'5月全部'!D:D,'5月全部'!M:M,0,1) -> 互斥 | H2583: =_xlfn.XLOOKUP(F2583,'5月全部'!D:D,'5月全部'!J:J,0,1) -> 满69减40（品20） | I2583: 46160 | J2583: 46160 | K2583: 6901035608602 | L2583: 青岛啤酒11度经典罐啤33ml*24/箱
A2584: 青岛啤酒 | B2584: 青岛啤酒 | C2584: =_xlfn.XLOOKUP(F2584,'5月全部'!D:D,'5月全部'!A:A,0,1) -> 单品牌券 | D2584: =_xlfn.XLOOKUP(F2584,'5月全部'!D:D,'5月全部'!G:G,0,1) -> 黑龙江 | E2584: =_xlfn.XLOOKUP(F2584,'5月全部'!D:D,'5月全部'!F:F,0,1) -> 便利 | F2584: 青啤黑龙江便利-5月满69减40（品20） | G2584: =_xlfn.XLOOKUP(F2584,'5月全部'!D:D,'5月全部'!M:M,0,1) -> 互斥 | H2584: =_xlfn.XLOOKUP(F2584,'5月全部'!D:D,'5月全部'!J:J,0,1) -> 满69减40（品20） | I2584: 46160 | J2584: 46160 | K2584: 6901035609272 | L2584: 青岛啤酒经典11度330*24罐啤
A2585: 青岛啤酒 | B2585: 青岛啤酒 | C2585: =_xlfn.XLOOKUP(F2585,'5月全部'!D:D,'5月全部'!A:A,0,1) -> 单品牌券 | D2585: =_xlfn.XLOOKUP(F2585,'5月全部'!D:D,'5月全部'!G:G,0,1) -> 黑龙江 | E2585: =_xlfn.XLOOKUP(F2585,'5月全部'!D:D,'5月全部'!F:F,0,1) -> 便利 | F2585: 青啤黑龙江便利-5月满69减40（品20） | G2585: =_xlfn.XLOOKUP(F2585,'5月全部'!D:D,'5月全部'!M:M,0,1) -> 互斥 | H2585: =_xlfn.XLOOKUP(F2585,'5月全部'!D:D,'5月全部'!J:J,0,1) -> 满69减40（品20） | I2585: 46160 | J2585: 46160 | K2585: 6901035604284 | L2585: 青岛啤酒经典10度500ml/瓶
A2586: 青岛啤酒 | B2586: 青岛啤酒 | C2586: =_xlfn.XLOOKUP(F2586,'5月全部'!D:D,'5月全部'!A:A,0,1) -> 单品牌券 | D2586: =_xlfn.XLOOKUP(F2586,'5月全部'!D:D,'5月全部'!G:G,0,1) -> 黑龙江 | E2586: =_xlfn.XLOOKUP(F2586,'5月全部'!D:D,'5月全部'!F:F,0,1) -> 便利 | F2586: 青啤黑龙江便利-5月满69减40（品20） | G2586: =_xlfn.XLOOKUP(F2586,'5月全部'!D:D,'5月全部'!M:M,0,1) -> 互斥 | H2586: =_xlfn.XLOOKUP(F2586,'5月全部'!D:D,'5月全部'!J:J,0,1) -> 满69减40（品20） | I2586: 46160 | J2586: 46160 | K2586: 6923740100059 | L2586: 青岛啤酒经典10度600ml/瓶
A2587: 青岛啤酒 | B2587: 青岛啤酒 | C2587: =_xlfn.XLOOKUP(F2587,'5月全部'!D:D,'5月全部'!A:A,0,1) -> 单品牌券 | D2587: =_xlfn.XLOOKUP(F2587,'5月全部'!D:D,'5月全部'!G:G,0,1) -> 黑龙江 | E2587: =_xlfn.XLOOKUP(F2587,'5月全部'!D:D,'5月全部'!F:F,0,1) -> 便利 | F2587: 青啤黑龙江便利-5月满69减40（品20） | G2587: =_xlfn.XLOOKUP(F2587,'5月全部'!D:D,'5月全部'!M:M,0,1) -> 互斥 | H2587: =_xlfn.XLOOKUP(F2587,'5月全部'!D:D,'5月全部'!J:J,0,1) -> 满69减40（品20） | I2587: 46160 | J2587: 46160 | K2587: 690103560220 | L2587: 青岛啤酒 11°P经典啤酒 330ml*24听/箱
A2588: 青岛啤酒 | B2588: 青岛啤酒 | C2588: =_xlfn.XLOOKUP(F2588,'5月全部'!D:D,'5月全部'!A:A,0,1) -> 单品牌券 | D2588: =_xlfn.XLOOKUP(F2588,'5月全部'!D:D,'5月全部'!G:G,0,1) -> 黑龙江 | E2588: =_xlfn.XLOOKUP(F2588,'5月全部'!D:D,'5月全部'!F:F,0,1) -> 便利 | F2588: 青啤黑龙江便利-5月满69减40（品20） | G2588: =_xlfn.XLOOKUP(F2588,'5月全部'!D:D,'5月全部'!M:M,0,1) -> 互斥 | H2588: =_xlfn.XLOOKUP(F2588,'5月全部'!D:D,'5月全部'!J:J,0,1) -> 满69减40（品20） | I2588: 46160 | J2588: 46160 | K2588: 6901035602204 | L2588: 青岛啤酒经典罐330ml*6*4/箱
A2589: 青岛啤酒 | B2589: 青岛啤酒 | C2589: =_xlfn.XLOOKUP(F2589,'5月全部'!D:D,'5月全部'!A:A,0,1) -> 单品牌券 | D2589: =_xlfn.XLOOKUP(F2589,'5月全部'!D:D,'5月全部'!G:G,0,1) -> 黑龙江 | E2589: =_xlfn.XLOOKUP(F2589,'5月全部'!D:D,'5月全部'!F:F,0,1) -> 便利 | F2589: 青啤黑龙江便利-5月满69减40（品20） | G2589: =_xlfn.XLOOKUP(F2589,'5月全部'!D:D,'5月全部'!M:M,0,1) -> 互斥 | H2589: =_xlfn.XLOOKUP(F2589,'5月全部'!D:D,'5月全部'!J:J,0,1) -> 满69减40（品20） | I2589: 46160 | J2589: 46160 | K2589: 6901035612173 | L2589: 青岛啤酒10度优质罐啤500ml*4*6/箱
A2590: 青岛啤酒 | B2590: 青岛啤酒 | C2590: =_xlfn.XLOOKUP(F2590,'5月全部'!D:D,'5月全部'!A:A,0,1) -> 单品牌券 | D2590: =_xlfn.XLOOKUP(F2590,'5月全部'!D:D,'5月全部'!G:G,0,1) -> 黑龙江 | E2590: =_xlfn.XLOOKUP(F2590,'5月全部'!D:D,'5月全部'!F:F,0,1) -> 便利 | F2590: 青啤黑龙江便利-5月满69减40（品20） | G2590: =_xlfn.XLOOKUP(F2590,'5月全部'!D:D,'5月全部'!M:M,0,1) -> 互斥 | H2590: =_xlfn.XLOOKUP(F2590,'5月全部'!D:D,'5月全部'!J:J,0,1) -> 满69减40（品20） | I2590: 46160 | J2590: 46160 | K2590: 6901035612128 | L2590: 青岛啤酒10度优质箱啤600ml*6/箱
... A3215: 青岛啤酒 | B3215: 青岛啤酒 | C3215: =_xlfn.XLOOKUP(F3215,'5月全部'!D:D,'5月全部'!A:A,0,1) -> 单品牌券 | D3215: =_xlfn.XLOOKUP(F3215,'5月全部'!D:D,'5月全部'!G:G,0,1) -> 辽宁 | E3215: =_xlfn.XLOOKUP(F3215,'5月全部'!D:D,'5月全部'!F:F,0,1) -> 酒专营 | F3215: 青啤辽宁酒专营假期-5月满79减30（品17） | G3215: =_xlfn.XLOOKUP(F3215,'5月全部'!D:D,'5月全部'!M:M,0,1) -> 互斥 | H3215: =_xlfn.XLOOKUP(F3215,'5月全部'!D:D,'5月全部'!J:J,0,1) -> 满79减30（品20） | I3215: 46143 | J3215: 46147 | K3215: 6901035629966 | L3215: 青岛啤酒茉莉味白啤500mll*3/组
...

Sheet 华南ID
A1: 闪电仓 | E1: 酒专营 | I1: 便利店 | M1: KA超市
A2: 渠道名称 | B2: 渠道编码 | C2: 不参与机制备注 | E2: 渠道名称 | F2: 渠道编码 | G2: 不参与机制备注 | I2: 渠道名称 | J2: 渠道编码 | K2: 不参与机制备注 | M2: 渠道名称 | N2: 渠道编码 | O2: 不参与机制备注
A3: 百汇精品超市（前海店） | B3: 21257960 | C3: 区域下沉-青啤华南全渠道ID-5月满70减7 区域下沉-青啤华南全渠道ID-5月满100减20 | E3: 酒送送(汕头总店） | F3: 17945749 | I3: 小二街便利店(育德店) | J3: 16485246 | M3: 日日升超市(锦盈分店) | N3: 17889000
A4: 百汇精品超市（后海店） | B4: 20777226 | C4: 区域下沉-青啤华南全渠道ID-5月满70减7 区域下沉-青啤华南全渠道ID-5月满100减20 | E4: 酒多多云仓 | F4: 21494056 | I4: 小二街便利店(金莱特店) | J4: 15552710 | M4: 日日升超市(沙头分店) | N4: 17888998
A5: 百汇精品超市（红山店） | B5: 19657422 | C5: 区域下沉-青啤华南全渠道ID-5月满70减7 区域下沉-青啤华南全渠道ID-5月满100减20 | E5: 酒送送(光和店） | F5: 26431480 | I5: 小二街便利店(健威店) | J5: 15531719 | M5: 日日升超市(宝行分店) | N5: 17888996
A6: 百汇精品超市（八卦岭店） | B6: 18968893 | C6: 区域下沉-青啤华南全渠道ID-5月满70减7 区域下沉-青啤华南全渠道ID-5月满100减20 | E6: 万酒全(东裕园南区店) | F6: 27380556 | I6: 小二街便利店(珑城半山店) | J6: 15023464 | M6: 日日升超市(东海蓝湾分店) | N6: 17888994
A7: 百汇精品超市（光明店） | B7: 18782871 | C7: 区域下沉-青啤华南全渠道ID-5月满70减7 区域下沉-青啤华南全渠道ID-5月满100减20 | E7: 1919快喝（湘桥店） | F7: 24181726 | I7: 小二街便利店(迎宾店) | J7: 12623072 | M7: 日日升超市(广海分店) | N7: 17888990
A8: 百汇精品超市（西丽店） | B8: 18412788 | C8: 区域下沉-青啤华南全渠道ID-5月满70减7 区域下沉-青啤华南全渠道ID-5月满100减20 | E8: 酒速达 | F8: 29032060 | I8: 小二街啤酒博物馆(尚岭新筑店) | J8: 12132054 | M8: 日日升超市(鸿安分店) | N8: 17888989
A9: 百汇精品超市（宝安店） | B9: 17703143 | C9: 区域下沉-青啤华南全渠道ID-5月满70减7 区域下沉-青啤华南全渠道ID-5月满100减20 | E9: 1919酒类直供(万江石美店) | F9: 25028437 | I9: 小二街便利店(中天新地店) | J9: 9580131 | M9: 日日升超市(新华路分店) | N9: 17888978
A10: 百汇精品超市（罗湖店） | B10: 16806548 | C10: 区域下沉-青啤华南全渠道ID-5月满70减7 区域下沉-青啤华南全渠道ID-5月满100减20 | E10: 宸兴酒业（东城店） | F10: 18253464 | I10: 小二街便利店(南盛店 | J10: 6930324 | M10: 日日升超市(爱伦堡分店) | N10: 17888977
A11: 百汇精品超市（福田店） | B11: 16479165 | C11: 区域下沉-青啤华南全渠道ID-5月满70减7 区域下沉-青啤华南全渠道ID-5月满100减20 | E11: 1919酒类直供(厚街万科广场店) | F11: 18441781 | I11: 小二街便利店(滨港店) | J11: 6890892 | M11: 日日升超市(北江明珠分店) | N11: 17888973
A12: 百汇精品超市（南山店） | B12: 15432619 | C12: 区域下沉-青啤华南全渠道ID-5月满70减7 区域下沉-青啤华南全渠道ID-5月满100减20 | E12: 1919酒类直供(厚街鼎盛时代店) | F12: 19417247 | I12: 小二街便利店(双龙雅居店) | J12: 3226076 | M12: 日日升超市(乐平分店) | N12: 17888971
A13: 句鲸百货Mart（阳东店） | B13: 20805983 | E13: 1919酒类直供(厚街镇新塘店) | F13: 19543080 | I13: 小二街便利店(双龙店) | J13: 3146441 | M13: 日日升超市(新里程分店) | N13: 17888968
A14: 鲸GO生活超市（天安云谷店） | B14: 19943209 | C14: 区域下沉-青啤华南全渠道ID-5月满70减7 区域下沉-青啤华南全渠道ID-5月满100减20 | E14: 1919酒类直供(凤岗天安店) | F14: 14664620 | I14: 七酷（台山东郊路0211店） | J14: 16212375 | M14: 日日升超市(圆坊都荟店) | N14: 17888962
A15: 句鲸百货Mart（江城店） | B15: 19859684 | E15: 1919酒类直供(大岭山金地格林店) | F15: 15408781 | I15: 七酷（台山市舜德路0238店） | J15: 12408494 | M15: 日日升超市(德信店) | N15: 17888958
A16: 句鲸百货Mart（南海店） | B16: 19531183 | E16: 1919酒类直供(东莞鼎峰尚境店) | F16: 17602015 | I16: 七酷（江门开平水口嘉兴北路01157店） | J16: 21089650 | M16: 日日升超市(保利分店) | N16: 17888957
A17: 鲸GO生活超市（梅林店） | B17: 19254068 | C17: 区域下沉-青啤华南全渠道ID-5月满70减7 区域下沉-青啤华南全渠道ID-5月满100减20 | E17: 1919酒类直供(塘厦丰腾大厦店) | F17: 22354837 | I17: 七酷(开平东汇城01139店) | J17: 17735610 | M17: 日日升超市(恒达分店) | N17: 17888956
A18: 句鲸百货Mart（龙岗店） | B18: 19187987 | E18: 三合酒业洋酒红酒啤酒（南城店） | F18: 9680350 | I18: 七酷（开平东汇城一期01169店） | J18: 26448718 | M18: 日日升超市(耀华分店) | N18: 17888955
A19: 句鲸百货Mart（平湖店） | B19: 19187986 | E19: 粤酒易信兴 | F19: 18735953 | I19: 七酷（开平升平路0120店） | J19: 16212397 | M19: 日日升超市(碧桂园分店) | N19: 17888954
A20: 鲸GO生活超市（大浪店） | B20: 19180546 | C20: 区域下沉-青啤华南全渠道ID-5月满70减7 区域下沉-青啤华南全渠道ID-5月满100减20 | E20: 1919快喝（府又店） | F20: 20639960 | I20: 七酷（太和村01106店） | J20: 16387858 | M20: 广泰超市（城南店） | N20: 18203129
A21: 鲸GO生活超市（观澜店） | B21: 18920638 | C21: 区域下沉-青啤华南全渠道ID-5月满70减7 区域下沉-青啤华南全渠道ID-5月满100减20 | E21: 1919快喝（北滘万科店） | F21: 26089076 | I21: 七酷（江门开平水口中山西路01155店） | J21: 21089367 | M21: 广泰超市（图强店） | N21: 4641034
A22: 鲸GO生活超市（国贸店） | B22: 18417170 | C22: 区域下沉-青啤华南全渠道ID-5月满70减7 区域下沉-青啤华南全渠道ID-5月满100减20 | E22: 1919快喝（乐从沙岗店） | F22: 26089077 | I22: 七酷（阳江阳春尚品星寓06042店） | J22: 18911125 | M22: 广泰超市（盐步市场店） | N22: 4641033
A23: 鲸GO生活超市（太安店） | B23: 18417026 | C23: 区域下沉-青啤华南全渠道ID-5月满70减7 区域下沉-青啤华南全渠道ID-5月满100减20 | E23: 1919快喝（松园新城店） | F23: 26089068 | I23: 七酷（开平农贸市场店01145店） | J23: 18782208 | M23: 广泰超市（松岗店） | N23: 4640812
A24: 鲸GO生活超市（宝安中心店） | B24: 17564421 | C24: 区域下沉-青啤华南全渠道ID-5月满70减7 区域下沉-青啤华南全渠道ID-5月满100减20 | E24: 1919快喝（翠竹店） | F24: 24940226 | I24: 七酷(台山锦绣二期店) | J24: 17796090 | M24: 广泰超市（沥中店） | N24: 4640811
A25: 鲸GO生活超市（下沙店） | B25: 17564463 | C25: 区域下沉-青啤华南全渠道ID-5月满70减7 区域下沉-青啤华南全渠道ID-5月满100减20 | E25: 1919快喝（范沙店） | F25: 22893361 | I25: 七酷（大江翔信0249店） | J25: 16212376 | M25: 广泰超市（金叶店） | N25: 4640810
A26: 鲸GO生活超市（南城店） | B26: 17313015 | C26: 区域下沉-青啤华南全渠道ID-5月满70减7 区域下沉-青啤华南全渠道ID-5月满100减20 | E26: 1919快喝（同兴路店） | F26: 21081905 | I26: 七酷（阳江阳东滨江花园06028店） | J26: 16414698 | M26: 广泰超市（总店） | N26: 4640809
A27: 鲸GO生活超市（西丽店） | B27: 17189179 | C27: 区域下沉-青啤华南全渠道ID-5月满70减7 区域下沉-青啤华南全渠道ID-5月满100减20 | E27: 1919快喝（外环路店） | F27: 24940229 | I27: 七酷（祥龙敬业路0193店） | J27: 15056402 | M27: 广泰超市（喜购店） | N27: 4640806
A28: 鲸GO生活超市（东城店） | B28: 16488920 | C28: 区域下沉-青啤华南全渠道ID-5月满70减7 区域下沉-青啤华南全渠道ID-5月满100减20 | E28: 1919快喝（泰山路店） | F28: 24940228 | I28: 七酷（江门蓬江华盛路二店0335店） | J28: 20176006 | M28: 广泰超市（花苑店） | N28: 4640805
A29: 鲸GO生活超市（沙井店） | B29: 16488868 | C29: 区域下沉-青啤华南全渠道ID-5月满70减7 区域下沉-青啤华南全渠道ID-5月满100减20 | E29: 1919酒类直供（环市东路店） | F29: 18632401 | I29: 七酷(台山锦绣花园3期0220店) | J29: 16212387 | M29: 广泰超市（润和店） | N29: 4640802
A30: 鲸GO生活超市（华强北店） | B30: 15641831 | C30: 区域下沉-青啤华南全渠道ID-5月满70减7 区域下沉-青啤华南全渠道ID-5月满100减20 | E30: 1919酒类直供（南庄大道店） | F30: 19416557 | I30: 七酷（台山幸福里0208店） | J30: 16660305 | M30: 广泰超市（凯欣店） | N30: 4640800
A31: 鲸GO生活超市（坂田店） | B31: 15466839 | C31: 区域下沉-青啤华南全渠道ID-5月满70减7 区域下沉-青啤华南全渠道ID-5月满100减20 | E31: 1919酒类直供（碧桂园华府店） | F31: 203336004 | I31: 七酷（台山东方华城0218店） | J31: 16212410 | M31: 广泰超市（东海店） | N31: 4640799
... A45: 熊猫很忙便利超市（平湖店） | B45: 20712458 | C45: 区域下沉-青啤华南全渠道ID-5月满70减7 区域下沉-青啤华南全渠道ID-5月满100减20 | E45: 懒象送酒（万达广场店） | F45: 30507681 | I45: 七酷（开平人民西路0189店） | J45: 16212415 | M45: 茶园商场(丽江东门店) | N45: 15547516
A46: 熊猫很忙便利超市（大芬店） | B46: 20688446 | C46: 区域下沉-青啤华南全渠道ID-5月满70减7 区域下沉-青啤华南全渠道ID-5月满100减20 | E46: 国洋烟酒行（福田岗厦卓越店） | F46: 29222465 | G46: 区域下沉-青啤华南全渠道ID-5月满70减7 区域下沉-青啤华南全渠道ID-5月满100减20 | I46: 七酷（江门蓬江环市二路0339店） | J46: 21104863 | M46: 茶园商场(南朗店) | N46: 15547514
A47: 优购哆生活超市(平湖店) | B47: 21664767 | C47: 区域下沉-青啤华南全渠道ID-5月满70减7 区域下沉-青啤华南全渠道ID-5月满100减20 | E47: 国洋烟酒行（坪山安荟邻店） | F47: 29215257 | G47: 区域下沉-青啤华南全渠道ID-5月满70减7 区域下沉-青啤华南全渠道ID-5月满100减20 | I47: 七酷（开平大福中路派出所0126店） | J47: 16212405 | M47: 茶园商场(京西店) | N47: 15547513
A48: 优购哆生活超市(长圳店) | B48: 21391380 | C48: 区域下沉-青啤华南全渠道ID-5月满70减7 区域下沉-青啤华南全渠道ID-5月满100减20 | E48: 国洋烟酒行（宝安中粮大悦城店） | F48: 28771445 | G48: 区域下沉-青啤华南全渠道ID-5月满70减7 区域下沉-青啤华南全渠道ID-5月满100减20 | I48: 七酷（开平长振路01148店） | J48: 18888545 | M48: 茶园商场(超朗店) | N48: 15547512
A49: 优购哆生活超市(桥头店) | B49: 20942911 | C49: 区域下沉-青啤华南全渠道ID-5月满70减7 区域下沉-青啤华南全渠道ID-5月满100减20 | E49: 国洋烟酒行（福田印力中心店） | F49: 27826236 | G49: 区域下沉-青啤华南全渠道ID-5月满70减7 区域下沉-青啤华南全渠道ID-5月满100减20 | I49: 七酷（开平百润花园0182店） | J49: 16212401 | M49: 茶园商场(卢边市场店) | N49: 15547511
A50: 优购哆生活超市(四联店) | B50: 20942907 | C50: 区域下沉-青啤华南全渠道ID-5月满70减7 区域下沉-青啤华南全渠道ID-5月满100减20 | E50: 国洋烟酒行（龙华星河iCO店） | F50: 27787965 | G50: 区域下沉-青啤华南全渠道ID-5月满70减7 区域下沉-青啤华南全渠道ID-5月满100减20 | I50: 七酷(江门蓬江华盛路0322店) | J50: 17491141 | M50: 万民超市（龙归店） | N50: 16031772
A51: 优购哆生活超市(坂田店) | B51: 20942899 | C51: 区域下沉-青啤华南全渠道ID-5月满70减7 区域下沉-青啤华南全渠道ID-5月满100减20 | E51: 国洋烟酒行（南山后海店） | F51: 27300842 | G51: 区域下沉-青啤华南全渠道ID-5月满70减7 区域下沉-青啤华南全渠道ID-5月满100减20 | I51: 七酷（开平骏景华庭01128店） | J51: 17157342 | M51: 万民超市（石井店） | N51: 16418219
A52: 优购哆生活超市(沙井店) | B52: 20942891 | C52: 区域下沉-青啤华南全渠道ID-5月满70减7 区域下沉-青啤华南全渠道ID-5月满100减20 | E52: 国洋烟酒行（盐田壹海城店） | F52: 27180364 | G52: 区域下沉-青啤华南全渠道ID-5月满70减7 区域下沉-青啤华南全渠道ID-5月满100减20 | I52: 七酷（开平轩汇豪庭北门01167店） | J52: 25337968 | M52: 万民超市（大石店） | N52: 16418208
A53: 优购哆生活超市(合水口店) | B53: 20587817 | C53: 区域下沉-青啤华南全渠道ID-5月满70减7 区域下沉-青啤华南全渠道ID-5月满100减20 | E53: 国洋烟酒行（南山盒马水湾店） | F53: 27179610 | G53: 区域下沉-青啤华南全渠道ID-5月满70减7 区域下沉-青啤华南全渠道ID-5月满100减20 | I53: 七酷(丰乐路世纪花源店) | J53: 17491462 | M53: 万民超市（天河店） | N53: 24082523
...

Sheet 快送熊
A1: 地址信息1 | B1: 省份 | C1: 美团店名 | D1: 美团店铺id
A2: 福建省厦门市思明区新景禾祥高峰会后滨东路6-166京东便利店 | B2: 福建省 | C2: 京东便利店（厦门店1） | D2: 17282896
A3: 福建省厦门市湖里区尚忠社543号102室之五 | B3: 福建省 | C3: 京东便利店（尚忠店） | D3: 19710123
A4: 福建省厦门市湖里区金山路2103号之二 | B4: 福建省 | C4: 京东便利店（软件园二期店） | D4: 19351335
A5: 福建省厦门市湖里区双浦东里31号104室之二（法律文书送达地址） | B5: 福建省 | C5: 京东便利店（厦门店2） | D5: 19349118
A6: 广东省佛山市顺德区大良街道金榜社区政通路4号家乐村4栋101铺之一 | B6: 广东省 | C6: 京东便利店（顺德店） | D6: 18732543
A7: 福建省厦门市集美区英瑶路569号201室 | B7: 福建省 | C7: 满佳喜超市（集美中心店） | D7: 30370783
A8: 福建省泉州市安溪县城厢镇土楼村内土楼175号 | B8: 福建省 | C8: 京东便利店（安溪中心店） | D8: 18691616
A9: 福建省莆田市城厢区龙桥街道后山路186号101室 | B9: 福建省 | C9: 京东便利店（莆田中心店） | D9: 18757145
A10: 福建省泉州市石狮市镇中路155号中骏商城中骏 商场B031室 | B10: 福建省 | C10: 京东便利店（石狮店） | D10: 18895775
A11: 福建省泉州市晋江市桂泉路57-12号、57-13号 | B11: 福建省 | C11: 京东便利店（晋江万达店） | D11: 19020333
A12: 广东省佛山市顺德区容桂街道容山社区乐安南路5号二层之一 | B12: 广东省 | C12: 京东便利店（容桂中心店） | D12: 18983147
... A418: 广东省佛山市南海区狮山镇松岗桃园三路1号首层商铺之二 | B418: 广东省 | C418: 仓鼠宜佳超市（松岗店） | D418: 32022707

Sheet 辽宁ID
A1: 闪电仓ID | D1: 酒专营ID | G1: 散店
A2: 荣顺生活超市（捷山街店） | B2: =VLOOKUP(A2,[1]辽宁!$E:$F,2,0) -> d7772ed95222df9e67d5892b26179624 | D2: 门店名称 | E2: 加密ID | G2: 52701869 | H2: LS青岛啤酒鲜啤吧
A3: 迪全超市（甘区店） | B3: =VLOOKUP(A3,[1]辽宁!$E:$F,2,0) -> ed2d8622a4746b04e0dd471feeb4a69a | D3: 飘轩烟酒茶（建设大路店） | E3: e145bc59996cfcaf0841243c6ad1cfc0 | G3: 17399204 | H3: 鲜啤吧
A4: 佰家生活超市（机场店） | B4: =VLOOKUP(A4,[1]辽宁!$E:$F,2,0) -> 4776d48bc244e1763e27667dfbd1c4cc | D4: 华元名优烟酒茶（湖南店） | E4: 14554fbb5554123883ed97fe7f833626 | G4: 12865984 | H4: 青岛啤酒鲜啤吧
A5: 芝福购 精品超市（大连店） | B5: =VLOOKUP(A5,[1]辽宁!$E:$F,2,0) -> bdb637959990a4813fcfa17871063dc9 | D5: 飘轩烟酒茶（南八店） | E5: 6b23b351745b422ce33e205df8ccedea | G5: 15309009 | H5: 啤酒小站宝地城店
A6: 珍惠达超市（大连店） | B6: 30272c7a0b198bcc840b8be09d8e1b77 | D6: 飘轩烟酒茶（小南店） | E6: 91ecd47a379c3d7b914cdecb01461963 | G6: 21171755 | H6: 鞍山鲜啤吧
A7: 云鲸选（中心店） | B7: =VLOOKUP(A7,[1]辽宁!$E:$F,2,0) -> beb4ceaca32d1d712e85e2232af2b1cc | D7: 华元名优烟酒茶(新兴店) | E7: ab52ed4306711afafc61546a5a2c76de | G7: 26166236 | H7: 青岛啤酒鲜酒吧
A8: 星际便利（中山店） | B8: =VLOOKUP(A8,[1]辽宁!$E:$F,2,0) -> bf002910fbc472b3b665a8de5656a089 | D8: 华元名优烟酒茶（九中店） | E8: 511a53726908745bbc002c11396f7619 | G8: 18481072 | H8: YJ青岛鲜啤吧
A9: 优购哆超市（大连中心店） | B9: 155dd9f7d5a8391c3420c1f80bc50668 | D9: 飘轩烟酒茶（于洪店） | E9: 7ea712aefb3637665683828f26749003 | G9: 15318625 | H9: YJ鲜啤屋
A10: 优购哆超市（七贤岭店） | B10: 130472793ed8d7085ff0c354e058b9af | D10: 飘轩烟酒茶（苏家屯凤鸣店） | E10: 784db2d8c08bcb2fad76a4f7b70bda00 | G10: 11658321 | H10: S鲜啤吧
A11: AA·百货超市（华南店） | B11: b707ed69134332e61fc5c599dd41094f | D11: 飘轩烟酒茶（铁岭店） | E11: bd3471606f6ec9a52715f8d6fe6bc793 | G11: 30551206 | H11: 乐小二·连锁超市（中街店）
A12: 万佳超市 | B12: 93d8de9225561d520a928fb24e2e9fe4 | D12: 飘轩烟酒茶（兴工店） | E12: fe3ecc99e7a2fdcb30828e770ab3c3df | G12: 12159783 | H12: 财富家超市(华君店)
A13: 共橙24小时超市（大连普兰中心路店） | B13: 3da540f3f085623afd9dbbd9fb7823cd | D13: 飘轩烟酒茶（奉天街店） | E13: 0662063af9783419689154883d566fda | G13: 3246520 | H13: 财富家超市(锦联店)
A14: 共橙24小时超市（大连软件园路店） | B14: c0a8e060784f3943c4ef4d77b8262939 | D14: 飘轩烟酒茶（五中店） | E14: 7d68faa3c2fe1a3e26a131d3287d253f | G14: 3243928 | H14: 财富春天购物中心
A15: 共橙24小时超市（大连中山店） | B15: 8c662ca6990072b7c18d319f2276f6b9 | D15: 飘轩烟酒茶（大西店） | E15: 0164c95ad19733de0696fe62c2db32e8 | G15: 19534036 | H15: S真食惠生鲜百货超市
A16: 共橙24小时超市（喀左建设路店） | B16: 1e9dc9047e57d386b6ef6f35970b5cda | D16: 东业烟酒茶（新华街店） | E16: 316c81598a5a52e2c86b6d71748d8e60 | G16: 28643021 | H16: S爱芯超市
A17: 共橙24小时超市（建昌县红旗街店） | B17: 50a90d279c733c322f2306fc3c581a85 | D17: 飘轩烟酒茶（鞍山店） | E17: 7ee90a023540133d6ba963387c3d6f6b | G17: 9093739 | H17: 鑫丰旺超市
A18: 共橙24小时超市（沈阳苏家屯店） | B18: 2878f6ce8d89f1260e7d38aff1c81d3d | D18: H9进口啤酒（洋酒、红酒、啤酒） | E18: 2779950b5a851a26e18c793a03db4d4e | G18: 5048520 | H18: 乐家家超市
A19: 共橙24小时超市（营口公园路店） | B19: 559ce087dbf44cb783dcebb89b647eca | D19: 满小酌Club（沈阳开发区店） | E19: 3227c9c787cea609d61d58b65f1e17f7 | G19: 21551944 | H19: s信赖源综合超市
A20: 共橙24小时超市（双台子店） | B20: cf7401c14b5d4306bcbd9ae75ae144d9 | D20: 酒快送 | E20: 975e0d5544679b43fb0dac9339bf8598 | G20: 9565429 | H20: LS甘井子大红福超市
A21: 共橙24小时超市（沈阳新民店） | B21: 14a80b674be7e18200dd5c0d6ab8064d | D21: 双鸿酒业酒类直供(朗云街店) | E21: #N/A | G21: 9565149 | H21: LS锦绣大红福超市
A22: 共橙24小时超市（西丰育英路店） | B22: a7c1df448c7cd64f615225f18d164542 | D22: 起荋丝进口酒礼（建设大路店） | E22: 3fa25671b20a9a8fb489dc4d4646d45b | G22: 9814021 | H22: LS前程街万诚隆超市
A23: 共橙24小时超市（明山店） | B23: f08ca82b80fd6f482b8f5705b4558b26 | D23: 起荋丝进口酒礼（文大路店） | E23: 5ce9ffc69906ff759e4ba620dd68b7f5 | G23: 10802189 | H23: LS王家桥大红福仓储超市
A24: 共橙24小时超市（瓦房店店） | B24: add62b5282c09b60f29a4c8a33d52f15 | D24: 起荋丝进口酒礼（东北大学店·酒·礼·茶） | E24: ebe501305598355e3f7baae47789a686 | G24: 9553501 | H24: LS前革大红福超市
A25: 共橙24小时超市（海城腾鳌镇店） | B25: 6d940cef5030314c5a3ca5c8e51189aa | D25: 起荋丝进口酒礼（浑南店·酒礼·茶） | E25: c39bdd699058d3b38e0563b3b76fe97b | G25: 10797224 | H25: LS中革大红福超市
A26: 共橙24小时超市（铁西南九东路店） | B26: a4a8df0cec17525f7a1bf3d850d111e7 | D26: 起荋丝进口酒礼（热闹路店.酒.礼.茶） | E26: 31cdac6fabf96ac5761e7590faa6791d | G26: 9553364 | H26: LS大红福超市美林园
A27: 共橙24小时超市（铁岭长青路店） | B27: 58e8f90fcb35fd17e4863c5925f8b382 | D27: 澳诺进口酒水折扣店（大连总店） | E27: b92fbe9f6b9378180eb0fae688dcce9b | G27: 16287909 | H27: LS南沙国亿大红福
A28: 共橙24小时超市（彰武解放大街店） | B28: 3a1d80ad45d8a5b883660441f92c5987 | D28: 澳诺进口酒水折扣店（中山店） | E28: ab7f086abeaf4b77898cbde3c4ab58a3 | G28: 30370696 | H28: 凌奥街万诚隆
A29: 共橙24小时超市（沈阳肇工南街店） | B29: a51ea561531b8c1063929274f80658ac | D29: 澳诺进口酒水折扣店（西岗店） | E29: 95441c773775553102a4d2c3b1ffddd5 | G29: 10577868 | H29: 大红福超市锦绣
A30: 共橙24小时超市（清原长岭街店） | B30: 3b1f6a6fd17b3893a67df7e5420b08b8 | D30: 澳诺进口酒水折扣店（山东路店） | E30: 172d89f94bf3914f68127c92d92d949d | G30: 2731921 | H30: 顺天成
A31: 共橙24小时超市（葫芦岛连山店） | B31: feb94542c18ba89a0def97abca2e3e4d | D31: 澳诺进口酒水折扣店（高新店） | E31: f7a4962c61887a8273117379944d4d85 | G31: 2426200 | H31: 心欣超市
A32: 共橙24小时超市（岫岩城东路店） | B32: a0bb5ee1a9667fa72e09f00c2d045fce | D32: 1919联合路店 | E32: 90114562161622f3731102663dc9b7af | G32: 12264039 | H32: 力达超市
A33: 共橙24小时超市（锦州店） | B33: d0e68d2ed4fbb7ba88cd79c11297d403 | D33: 怪兽酒窝（鸡尾酒，啤酒，长青店） | E33: 3aae864b65467653f3574188c364ae0a | G33: 2403190 | H33: 顺兴超市
... A61: 共橙24小时超市（铁西沈辽路店） | B61: 065007c7b4d63b7387b88d1f8ec7d05c | D61: 三叁·怪兽酒窝(于洪店.现调鸡尾酒.啤酒.洋酒） | E61: 7dd425376f04cf5b6fc1e61d872c6792 | G61: 2738438 | H61: S青春便利店学士街
A62: 共橙24小时超市（辽阳县人民街店） | B62: 998a11667b72ed7d02332535c082fbe0 | D62: P9进口酒水直供（美晟店） | E62: 28c3207d27c3ab16a0bb509878bc73ab
A63: 共橙24小时超市（台安县光明街店） | B63: 96a4cb96529626f3eb9e22ec5e5f16ac | D63: P9进口酒水直供（三木森店） | E63: 75573e2fdf598aaceed0655ccb66a705
A64: 共橙24小时超市（建平县文化街店） | B64: b96a980e76c19f757faa9d49baf9f9f7 | D64: P9进口酒水直供（沈辽店） | E64: 050f884194aa16ff623607a5bc091732
A65: 共橙24小时超市（丹东振兴店） | B65: 047e652b84b271d55633298f3c0eb782 | D65: 怪兽酒类直供（中街店，鸡尾酒，洋酒，红酒） | E65: 0e6d2be40b4894302dc4da166d2b47b9
A66: 共橙24小时超市（绥中新兴街店） | B66: 6240f4cc9d6011090b5d04efed28bf0e | D66: 怪兽酒窝（和平店.鸡尾酒.洋酒.红酒） | E66: 7222f461ac56815816bd32b5ef3f17b6
A67: 共橙24小时超市（盘锦兴隆台店） | B67: c0b6b9eb6521117a3c89bdc84fbfecda | D67: 怪兽酒窝（皇姑店,鸡尾酒，洋酒，红酒） | E67: 1d2b8093ee429fddebd17182e92b77bb
...

Sheet 甘肃ID
A1: 闪电仓ID | D1: 酒专营ID | G1: 超市ID
A2: 门店名称 | B2: 美团门店ID | D2: 门店名称 | E2: 美团门店ID | G2: 门店名称 | H2: 美团门店ID
A3: 嗨云购超市(清水店) | B3: 31097387 | D3: 酒庄直通安宁东路店 | E3: 30164077 | G3: 北京华联生活超市（白银店） | H3: 20642252
A4: 嗨云购超市(武山店) | B4: 31097639 | D4: 酒庄直通保利金香槟店 | E4: 31075490 | G4: 北京华联生活超市（银滩店） | H4: 20642247
A5: 嗨云购超市(天祝店) | B5: 30915165 | D5: 酒庄直通中海寰宇店 | E5: 31233325 | G5: 北京华联生活超市（金城珑园店） | H5: 20642245
A6: 嗨云购超市(门源店) | B6: 30915317 | D6: 酒庄直通五泉店 | E6: 31300643 | G6: 北京华联生活超市（交大店） | H6: 20642237
A7: 嗨云购超市(平川店) | B7: 30078446 | D7: 酒庄直通金昌北路店 | E7: 31766884 | G7: 北京华联生活超市(西湖1号店） | H7: 20642234
A8: 嗨云购超市(平安店) | B8: 29437881 | D8: 酒庄直通忠和镇万科店 | E8: 32037235 | G8: 北京华联生活超市（王府井店） | H8: 20642233
A9: 嗨云购超市(永靖店) | B9: 29335914 | D9: 酒号站（天源店） | E9: 29037790 | G9: 北京华联（红星店） | H9: 20642232
A10: 嗨云购超市(万达茂店) | B10: 29259688 | D10: 酒号站（临洮店） | E10: 29534549 | G10: BHG生活超市（飞天店） | H10: 20642230
A11: 嗨云购超市(海鸿店) | B11: 29297624 | D11: 酒号站（东湖小区店） | E11: 28550804 | G11: 北京华联生活超市（万辉店） | H11: 20642225
A12: 嗨云购超市(临夏中心广场店) | B12: 28983411 | D12: 酒号站（安宁店） | E12: 29193877 | G12: 北京华联生活超市（西固店） | H12: 20642223
A13: 嗨云购超市(秦州店) | B13: 27524609 | D13: 酒号站（西固四季青店） | E13: 31662281 | G13: 北京华联生活超市（名城广场店） | H13: 20642222
A14: 嗨云购超市(贺兰店) | B14: 27575179 | D14: 酒号站（老街店） | E14: 31577115 | G14: BHG生活超市（奥体中心店） | H14: 20642220
... A33: 嗨云购超市(西关店) | B33: 25445085 | D33: 金城易酒批（民生新天地店） | E33: 30734981 | G33: 华润万家格林小镇店 | H33: 11012273
A34: 嗨云购超市(城中店） | B34: 25034798 | D34: 金城易酒批（恒顺锦润悦府店） | E34: 28894861
A35: 嗨云购超市（合作店） | B35: 24829184 | D35: 金城易酒批（豪布斯卡店） | E35: 18989862
A36: 嗨云购超市（张掖店） | B36: 24575703 | D36: 大嘴快喝酒类专营（武山店） | E36: 32642791
A37: 嗨云购超市（敦煌店） | B37: 24353306 | D37: 大嘴快喝酒类专营（陇西店） | E37: 32575241
A38: 嗨云购超市（老街店） | B38: 24342759 | D38: 大嘴快喝酒类专营（武都店） | E38: 32564360
A39: 嗨云购超市（安宁店） | B39: 24000665 | D39: 大嘴快喝酒类专营（临夏店） | E39: 32563772
A40: 嗨云购超市（金昌店） | B40: 23146016 | D40: 大嘴快喝酒类专营（金昌店） | E40: 32558014
A41: 嗨云购超市（兰州店） | B41: 21829335 | D41: 大嘴快喝酒类专营（华亭店） | E41: 32544185
A42: 嗨云购超市（麦积店） | B42: 21602286 | D42: 大嘴快喝酒类专营（兰州新区店） | E42: 32541295
A43: 嗨云购超市（临洮店） | B43: 21622259 | D43: 大嘴快喝酒类专营（临洮店） | E43: 32539833
A44: 嗨云购超市（九州店） | B44: 21263712 | D44: 大嘴快喝酒类专营（天鹅湖店） | E44: 31648444
A45: 嗨云购超市（白银西区店） | B45: 21154215 | D45: 大嘴快喝酒类专营（九州店） | E45: 31617944
... A64: 小柴购（喜欢里店） | B64: 27151033 | D64: 1919快喝（西关中心店） | E64: 25926212
A65: 小柴购（二医院店） | B65: 25649328
A66: 小柴购超市（兰州店） | B66: 20278873
A67: 小柴购超市（东岗店） | B67: 24010166
A68: 小柴购超市（七里河店） | B68: 24094391
A69: 小柴购超市（雁滩店） | B69: 28238599
A70: 小柴购超市（西固店） | B70: 28056311
A71: 小柴购超市（安宁店） | B71: 24269352
A72: AA·百货超市（兰州店） | B72: 31282582
A73: 宅小熊超市(雁滩店) | B73: 29372435
A74: 宅小熊超市(城关店) | B74: 28374570
A75: 宅小熊超市(兰州店) | B75: 24271565
A76: 叮到超市 | B76: 30061812
...

Sheet 黑龙江ID
A1: 门店名称 | B1: 门店ID
A2: 隆源超市 | B2: 16423768
A3: 亿鑫食品超市 | B3: 2794139
A4: 汇鑫蔬菜水果粮油超市 | B4: 3582614
A5: 笑笑优鲜超市 | B5: 1205835260
A6: 浚博平价超市 | B6: 13753689
A7: 国忠超市（碧海蓬壶店） | B7: 19319897
A8: 万隆超市 | B8: 3723749
A9: 优品超市 | B9: 8114917
A10: 淘小丫仓储超市 | B10: 24032028
A11: 桥世酒库 | B11: 20498436
A12: 淘小丫超市 | B12: 27436821
A13: 淘小丫超市 | B13: 27223452
... A45: 大润发超市 | B45: 3620597

Sheet 贵州ID
A1: 27156806
A2: 29754969
A3: 11213710
A4: 28058518
A5: 28042931
A6: 28170719
A7: 27639918
A8: 27640426
A9: 27386740
A10: 28937163
A11: 29161153
A12: 29838040
... A621: 28707531

Sheet 河北ID
A1: 闪电仓 | B1: 终端名称 | C1: 门店ID | E1: 酒专营 | F1: 终端名称 | G1: 门店ID
A2: 闪电仓 | B2: 优仓达超市百货 | C2: 22875959 | E2: 酒专营 | F2: 俱酒汇天山海世界店 | G2: 28441040
A3: 闪电仓 | B3: 熊猫购（广安店）超市 | C3: 17850000 | E3: 酒专营 | F3: 俱酒汇万象城店 | G3: 28073359
A4: 闪电仓 | B4: 蜂鸟酷选超市（中冶店） | C4: 25594334 | E4: 酒专营 | F4: 俱酒汇万达广场店 | G4: 28381906
A5: 闪电仓 | B5: 汀喜兔优选（石家庄店） | C5: 30430189 | E5: 酒专营 | F5: 俱酒汇南高营店 | G5: 23783281
A6: 闪电仓 | B6: 优购哆超市（槐安西路店） | C6: 28654990 | E6: 酒专营 | F6: 俱酒汇中华大街店 | G6: 28073155
A7: 闪电仓 | B7: 优购哆超市（裕华店） | C7: 28096829 | E7: 酒专营 | F7: 俱酒汇上庄店 | G7: 30546544
A8: 闪电仓 | B8: 满佳喜超市（石家庄建华店） | C8: 27496762 | E8: 酒专营 | F8: 俱酒汇正定古城店 | G8: 29878351
A9: 闪电仓 | B9: 满佳喜超市（裕华店） | C9: 28739650 | E9: 酒专营 | F9: 俱酒汇正定店 | G9: 27698154
A10: 闪电仓 | B10: 满佳喜超市（新华中心店） | C10: 28020513 | E10: 酒专营 | F10: 俱酒汇翟营店 | G10: 20756625
A11: 闪电仓 | B11: 乐购达超市（盛邦花园） | C11: 25273437 | E11: 酒专营 | F11: 俱酒汇盛世名城店 | G11: 31276771
A12: 闪电仓 | B12: 乐购达超市（运河桥） | C12: 31578794 | E12: 酒专营 | F12: 俱酒汇芙蓉岛店 | G12: 31276279
A13: 闪电仓 | B13: 乐购达超市（梦工厂店） | C13: 28424798 | E13: 酒专营 | F13: 俱酒汇石家庄店 | G13: 28555218
... A38: 闪电仓 | B38: 柴小囤乐亭海港店 | C38: 28035400 | E38: 酒专营 | F38: 怪兽酒类直供 | G38: 29876643
A39: 闪电仓 | B39: 柴小囤驻马店平舆店 | C39: 28157263
A40: 闪电仓 | B40: 柴小囤驻马店驿城区店 | C40: 29913310
A41: 闪电仓 | B41: 超宜佳友谊大街店 | C41: 20119811
A42: 闪电仓 | B42: 小柴购店长安店 | C42: 21604084
A43: 闪电仓 | B43: 京东便利高新店 | C43: 26828168
A44: 闪电仓 | B44: 优速送新石店 | C44: 28104405
A45: 闪电仓 | B45: 乐购达友谊公园店 | C45: 30277318
A46: 闪电仓 | B46: 乐购达勒泰店 | C46: 31519767
A47: 闪电仓 | B47: 京东便利中山东路店 | C47: 30046486
A48: 闪电仓 | B48: 慕森塔北店 | C48: 21241022
A49: 闪电仓 | B49: 满佳喜石家庄店 | C49: 28148915
A50: 闪电仓 | B50: 乐购达空中花园店 | C50: 28946592
... A79: 闪电仓 | B79: 小柴购店长安店 | C79: 21604084

Sheet 山西ID
A1: 美团 | B1: 门店ID | C1: 门店名称 | D1: 省份名称 | E1: 城市名称 | F1: 物理品牌名称 | G1: 渠道类型 | H1: 加密ID
A2: 美团 | B2: 15941898 | C2: 万物到家超市(万达店) | D2: 山西省 | E2: 太原 | F2: 万物到家 | G2: 闪电仓 | H2: 049ea5ac48b63a2411cb250e7b0cfd23
A3: 美团 | B3: 24774380 | C3: 乐购达超市（世贸中心店） | D3: 山西省 | E3: 太原 | F3: 乐购达超市 | G3: 闪电仓 | H3: cf303ef4828005bcc2f0fc2d966022d8
A4: 美团 | B4: 28174699 | C4: 安心购超市（龙盛街店） | D4: 山西省 | E4: 太原 | F4: 安心购 | G4: 闪电仓 | H4: a7a7803ee9f27b461db84f541b17e131
A5: 美团 | B5: 19258163 | C5: 兔兔速购（百花谷店） | D5: 山西省 | E5: 太原 | F5: 兔兔速购 | G5: 闪电仓 | H5: ff29428f598e7109b25c3c76b2d20b75
A6: 美团 | B6: 19983827 | C6: 向阳超市（国体店） | D6: 山西省 | E6: 太原 | F6: 向阳超市 | G6: 闪电仓 | H6: 4dc7943d9e93a3006be4502f6a82d313
A7: 美团 | B7: 17788690 | C7: 宜家快送超市(万达店） | D7: 山西省 | E7: 太原 | F7: 宜家快送超市 | G7: 闪电仓 | H7: 747002bedf76ae1721d7a179d5ce8c10
A8: 美团 | B8: 25816855 | C8: 海豚购（运城店） | D8: 山西省 | E8: 运城 | F8: 海豚购 | G8: 闪电仓 | H8: a5b0307f9611fd44bc00040a254e97a7
A9: 美团 | B9: 28855701 | C9: 乐购达超市（龙城北街店） | D9: 山西省 | E9: 太原 | F9: 乐购达超市 | G9: 闪电仓 | H9: 79af43746b9bb2e0b02f9b5c6ad7c079
A10: 美团 | B10: 24976881 | C10: 超宜佳超市（侯马店) | D10: 山西省 | E10: 临汾 | F10: 超宜佳 | G10: 闪电仓 | H10: 6b1addb43237ba41388cd86dee8fbb80
A11: 美团 | B11: 29856877 | C11: 共橙24小时超市（晋中中都路店） | D11: 山西省 | E11: 晋中 | F11: 共橙 | G11: 闪电仓 | H11: 44588bdaecd75171969c62e0bd3a3344
A12: 美团 | B12: 24019699 | C12: 宅宅送超市（大同店） | D12: 山西省 | E12: 大同 | F12: 宅宅送 | G12: 闪电仓 | H12: 2696e26e17451546d6413e2937845eff
A13: 美团 | B13: 27246092 | C13: 星马快送超市（柳巷店） | D13: 山西省 | E13: 太原 | F13: 讯汇通 | G13: 闪电仓 | H13: fcda3b77775f68dc0cca5a2e1650b104
... A257: 美团 | B257: 18945009 | C257: 兔兔速购(万科店) | D257: 山西省 | E257: 太原 | F257: 兔兔速购 | G257: 闪电仓 | H257: a8763deb571f481ca8d33c965f972c6f
A258: 美团 | B258: 30148660 | C258: 兔兔速购（山西大学店） | D258: 山西省 | E258: 太原 | F258: 兔兔速购 | G258: 闪电仓 | H258: #N/A
A259: 美团 | B259: 30713690 | C259: 小仓生活（钟楼店） | D259: 山西省 | E259: 太原 | F259: 小仓生活 | G259: 闪电仓 | H259: f44701470289261f47dcbd127b7fe7e9
A260: 美团 | B260: 31042621 | C260: 小仓生活（大同大学店） | D260: 山西省 | E260: 大同 | F260: 小仓生活(大同大学店) | G260: 闪电仓 | H260: 35135b6080a849ce87f1680ceb6cf90c
A261: 美团 | B261: 30148660 | C261: 即购（山西大学店） | D261: 山西省 | E261: 太原 | F261: 即购 | G261: 闪电仓 | H261: ba449e77479c1f947ceed336c58549b4
A262: 美团 | B262: 30188539 | C262: 安心购万柏林 | D262: 山西省 | E262: 太原 | F262: 安心购 | G262: 闪电仓 | H262: 2bc1454ea02b71a1602fa59896079c5a
A263: 美团 | B263: 24446072 | C263: 华宇生活超市 | D263: 山西省 | E263: 太原 | F263: 华宇生活 | G263: 超市 | H263: 17854386e91f7a41f53b1f347ab7e368
A264: 美团 | B264: 31060185 | C264: 乐购达超市 | D264: 山西省 | E264: 太原 | F264: 乐购达 | G264: 闪电仓 | H264: #N/A
A265: 美团 | B265: 1010610 | C265: 宜家便利店（宅小熊超市） | D265: 山西省 | E265: 侯马 | F265: 宅小熊超市 | G265: 超市 | H265: #N/A
A266: 美团 | B266: 29174201 | C266: 京东便利 | D266: 山西省 | E266: 太原 | F266: 超市便利KA组 | G266: 便利 | H266: e7dcd09699d94d2039a9ab9f3b853d1a
A267: 美团 | B267: 28147416 | C267: 久久便利（南风新都汇店） | D267: 山西省 | E267: 运城 | F267: 久久便利超市 | G267: 超市 | H267: 43ad8912f887195a3da3f40dc8dfcabf
A268: 美团 | B268: 24932775 | C268: 厉臣便利店（襄汾锦华名苑店） | D268: 山西省 | E268: 临汾 | F268: 厉臣超市 | G268: 超市 | H268: c08d42f5256cdc35e9c87fecd0ebd54c
A269: 美团 | B269: 24830174 | C269: 宅小熊超市（晋城店） | D269: 山西省 | E269: 晋城 | F269: 宅小熊超市 | G269: 超市 | H269: f1080151e8693142803f8ef72619d7e1
A270: 美团 | B270: 24900753 | C270: 厉臣便利店（清徐县店） | D270: 山西省 | E270: 太原 | F270: 厉臣超市 | G270: 超市 | H270: 26cb001735cff2833f3ede23dcbb918a
A271: 美团 | B271: 25405377 | C271: 厉臣便利（寿阳县恒阳路店） | D271: 山西省 | E271: 晋中 | F271: 厉臣超市 | G271: 超市 | H271: 230616693c9a37e3b85e51ebce2681d9
A272: 美团 | B272: 21468319 | C272: 乐小二·斑马超市（晋中店） | D272: 山西省 | E272: 晋中 | F272: 乐的便利店 | G272: 便利 | H272: 556b0afe8342ec13e0365b92c0327a02
A273: 美团 | B273: 24405379 | C273: 京东便利店（万象城店） | D273: 山西省 | E273: 太原 | F273: 京东便利店 | G273: 便利 | H273: 108eb17993112bcdffd5e061d0103826
A274: 美团 | B274: 27872375 | C274: 宅小熊超市（河津店） | D274: 山西省 | E274: 运城 | F274: 宅小熊超市 | G274: 超市 | H274: 1af13452c0f6b4f47aa8a88bb5632b64
A275: 美团 | B275: 19966945 | C275: 京东便利店（城南仓店） | D275: 山西省 | E275: 太原 | F275: 京东便利店 | G275: 便利 | H275: a6ea467dc88d3c1230e6fd007a398555
A276: 美团 | B276: 28334712 | C276: 久久便利（金磊凤凰城店） | D276: 山西省 | E276: 运城 | F276: 久久便利超市 | G276: 超市 | H276: 9564113700cbcd6e1f631732f91e595c
A277: 美团 | B277: 26739839 | C277: 小马购建邦便利店 | D277: 山西省 | E277: 临汾 | F277: 小马购便利超市(直营) | G277: 超市 | H277: c546e2d03d772c41fcfa01749d5ca244
... A292: 美团 | B292: 24090925 | C292: 易捷速购（太原大王路店） | D292: 山西省 | E292: 太原 | F292: 易捷速购 | G292: 便利 | H292: 4753c1a5f35a2af48178be4b5725fb58
A293: 美团 | B293: 29793471 | C293: 臻百购24h便利店（振兴街店） | D293: 山西省 | E293: 大同 | G293: 超市 | H293: d3f3561746d47044c83de1e4ffd4c8b0
A294: 美团 | B294: 29797649 | C294: 全佳临·平价超市（广灵店） | D294: 山西省 | E294: 大同 | F294: 全佳临 | G294: 便利 | H294: f3cea5707ef231d2fbaec4c294a23e2a
A295: 美团 | B295: 29795403 | C295: 旺哆·惠选超市（广灵店） | D295: 山西省 | E295: 大同 | G295: 便利 | H295: f74bc6977be11a9840ad5f3e8e6c2942
A296: 美团 | B296: 14593443 | C296: 京东便利店（新建东街店） | D296: 山西省 | E296: 太原 | F296: 京东便利店 | G296: 便利 | H296: db0313a905272bf46a253042f46722fc
A297: 美团 | B297: 21425457 | C297: 1919快喝延陵路店 | D297: 山西省 | E297: 大同 | F297: 1919 | G297: 酒专 | H297: a38b50f9da393572037bcb863bb25557
...

Sheet 新疆ID
A1: 城市 | B1: 门店名称 | C1: 美团门店ID
A2: 伊宁市 | B2: 美时美刻（利群路店) | C2: 14694018
A3: 伊宁市 | B3: 美时美刻（福安国际店） | C3: 17860901
A4: 伊宁市 | B4: 美时美刻（胜利街店） | C4: 25073014
A5: 伊宁市 | B5: 云上购（山东路店） | C5: 20006352
A6: 伊宁市 | B6: 京东便利店（伊宁中心店） | C6: 23930358
A7: 伊宁市 | B7: 小柴购超市（伊宁中心店） | C7: 28094528
A8: 伊宁市 | B8: 快捷购精品超市（开发区店） | C8: 28894326
A9: 伊宁市 | B9: 快捷购精品超市（伊宁店） | C9: 27606343
A10: 伊宁市 | B10: 快捷购精品超市（上海城店） | C10: 31521700
A11: 伊宁市 | B11: 闪仓便利店（伊宁中心店) | C11: 21624446
A12: 伊宁市 | B12: 闪仓便利店（开发区店） | C12: 27887725
A13: 博乐店 | B13: 宅小熊（博乐店） | C13: 30793455
... A247: 吐鲁番 | B247: 元气小二超市（吐鲁番店） | C247: 24384852

Sheet 新银麦ID
A1: 满29减8 | D1: 满49减12 | G1: 满29减5 | J1: 满99减26 | M1: 满39减9
A2: 15941617 | B2: 卖可便利店（意林公馆店） | D2: 乐又达快送超市（沂州店） | E2: 26717482 | G2: 15941617 | H2: 卖可便利店（意林公馆店） | J2: 歪马送酒（双月湖店） | K2: 27487384 | M2: 青岛啤酒新鲜直送（开阳路店） | N2: 20347015
A3: 20971322 | B3: 卖可便利店（高尔夫庄园二店） | D3: 乐又达快送超市（北园路店） | E3: 28218931 | G3: 20971322 | H3: 卖可便利店（高尔夫庄园二店） | J3: 歪马送酒（颐高上海街店） | K3: 27899283 | M3: 青岛啤酒新鲜直送（双月园路青啤地产店） | N3: 20352615
A4: 26758290 | B4: 卖可便利店（琅琊古城东门店） | D4: 乐又达快送超市（红星店） | E4: 21466478 | G4: 26758290 | H4: 卖可便利店（琅琊古城东门店） | J4: 歪马送酒（人民大街店） | K4: 27705901 | M4: 青岛啤酒新鲜直送（义堂店） | N4: 20386942
A5: 27536303 | B5: 卖可便利店（天泰华府北区店） | D5: 乐又达快送超市（双月湖店） | E5: 28168007 | G5: 27536303 | H5: 卖可便利店（天泰华府北区店） | J5: 歪马送酒（中南樾府店） | K5: 27377357 | M5: 青岛啤酒新鲜直送（化武路店） | N5: 18401568
A6: 21634906 | B6: 卖可便利店（滨河阳光店） | D6: 乐又达快送超市（兰陵店） | E6: 30019577 | G6: 21634906 | H6: 卖可便利店（滨河阳光店） | J6: 歪马送酒（创业大厦店） | K6: 27032574 | M6: 青岛啤酒新鲜直送（费县店） | N6: 5351812
A7: 23820922 | B7: 卖可便利店（东方城店） | D7: 乐又达快送超市（吾悦广场店） | E7: 28964319 | G7: 23820922 | H7: 卖可便利店（东方城店） | J7: 歪马送酒（开阳路店） | K7: 27377359 | M7: 青岛啤酒新鲜直送（兰山路店） | N7: 20344648
A8: 20219685 | B8: 卖可便利店（奥德滨江湾店） | D8: 乐又达快送超市（滨河店） | E8: 31588876 | G8: 20219685 | H8: 卖可便利店（奥德滨江湾店） | J8: 歪马送酒（皇山店） | K8: 27706519 | M8: 青岛啤酒新鲜直送（大学城店） | N8: 17524880
A9: 13695426 | B9: 卖可便利店（中元御桂园店） | D9: 袋鼠甄选超市（涑河街店） | E9: 28575821 | G9: 13695426 | H9: 卖可便利店（中元御桂园店） | J9: 歪马送酒（金雀山店） | K9: 27030691 | M9: 青岛啤酒新鲜直送（果园路南道店） | N9: 17496314
A10: 30784966 | B10: 卖可便利店（浮来春公馆店） | D10: 袋鼠甄选超市（万象汇店） | E10: 30554276 | G10: 30784966 | H10: 卖可便利店（浮来春公馆店） | J10: 歪马送酒（龙盛乾园店） | K10: 27032571 | M10: 青岛啤酒新鲜直送（观澜府店） | N10: 17071052
A11: 17256979 | B11: 卖可便利店（钓鱼一号院二店） | D11: 袋鼠甄选·生活超市（南坊店） | E11: 31303851 | G11: 17256979 | H11: 卖可便利店（钓鱼一号院二店） | J11: 歪马送酒（华前店） | K11: 27030690 | M11: 青岛啤酒新鲜直送（红旗路店） | N11: 13929302
A12: 9719680 | B12: 卖可便利店（金鼎二店） | D12: 袋鼠甄选超市（北园路店） | E12: 31679508 | G12: 9719680 | H12: 卖可便利店（金鼎二店） | J12: 歪马送酒（临沭店） | K12: 28748586 | M12: 青岛啤酒新鲜直送（吾悦店） | N12: 18116752
A13: 15297788 | B13: 卖可便利店（钓鱼一号院店） | D13: 快捷购精品超市（临沂店） | E13: 19598023 | G13: 15297788 | H13: 卖可便利店（钓鱼一号院店） | J13: 歪马送酒（城市广场店） | K13: 31863385 | M13: 青岛啤酒新鲜直送（御山河店） | N13: 17704894
... A16: 31863802 | B16: 卖可便利店（华润凯旋门店） | D16: 便品优选新华路店 | E16: 27629957 | G16: 31863802 | H16: 卖可便利店（华润凯旋门店） | J16: 歪马送酒（君瑞城店） | K16: 26800892 | M16: 青岛啤酒新鲜直送（王庄路店） | N16: 24501338
A17: 31728635 | B17: 卖可便利店（悦澜山店） | D17: 小柴购临沂店 | E17: 23863156 | G17: 31728635 | H17: 卖可便利店（悦澜山店）
A18: 7368016 | B18: 卖可便利店（金鼎国际店） | D18: 安心购超市（南坊店） | E18: 31416725 | G18: 7368016 | H18: 卖可便利店（金鼎国际店）
A19: 27599239 | B19: 卖可便利店（万科城如园店） | D19: 优团生活超市（陶然路店） | E19: 21034269 | G19: 27599239 | H19: 卖可便利店（万科城如园店）
A20: 24834137 | B20: 卖可便利店（沂河一英里店） | D20: 优团生活超市（沂州路） | E20: 21034186 | G20: 24834137 | H20: 卖可便利店（沂河一英里店）
A21: 9004458 | B21: 卖可便利店（汇通天下店） | D21: 优团生活超市（沂蒙路店） | E21: 18318639 | G21: 9004458 | H21: 卖可便利店（汇通天下店）
A22: 26779568 | B22: 卖可便利店（颐高上海街三期店） | D22: 优团生活精品超市（薛城店） | E22: 21387043 | G22: 26779568 | H22: 卖可便利店（颐高上海街三期店）
A23: 15647943 | B23: 卖可便利店（八里屯店） | D23: 柴小囤精品超市（南坊店） | E23: 19128692 | G23: 15647943 | H23: 卖可便利店（八里屯店）
A24: 12409748 | B24: 卖可便利店（奥正诚园店） | D24: 优购哆超市（齐鲁园） | E24: 27669039 | G24: 12409748 | H24: 卖可便利店（奥正诚园店）
A25: 11382916 | B25: 卖可便利店（城开东岸店） | D25: 环购鲸生活超市（临沂店） | E25: 25264255 | G25: 11382916 | H25: 卖可便利店（城开东岸店）
A26: 10017201 | B26: 卖可便利店（新华路店） | D26: 全之百货连锁超市(兰山总店） | E26: 14542804 | G26: 10017201 | H26: 卖可便利店（新华路店）
A27: 9341095 | B27: 卖可便利店（优卡空间店） | D27: 天猫小店（理想家便利店） | E27: 1867261 | G27: 9341095 | H27: 卖可便利店（优卡空间店）
A28: 12409750 | B28: 卖可便利店（威特天元广场店） | D28: 蓝岛乐家便利店（东方购物广场店） | E28: 19076018 | G28: 12409750 | H28: 卖可便利店（威特天元广场店）
... A45: 17686605 | B45: 卖可便利店（金猴名居店） | D45: 小柴达超市(新城店) | E45: 28767709 | G45: 17686605 | H45: 卖可便利店（金猴名居店）
A46: 11544308 | B46: 卖可便利店（金鹰花园店） | G46: 11544308 | H46: 卖可便利店（金鹰花园店）
A47: 4526593 | B47: 卖可便利店（万泰商贸城店） | G47: 4526593 | H47: 卖可便利店（万泰商贸城店）
A48: 23104293 | B48: 卖可便利店（东城金谷店） | G48: 23104293 | H48: 卖可便利店（东城金谷店）
A49: 22873368 | B49: 卖可便利店（泰鲁时代城店） | G49: 22873368 | H49: 卖可便利店（泰鲁时代城店）
A50: 11544309 | B50: 卖可便利店（金泰舒格兰二店） | G50: 11544309 | H50: 卖可便利店（金泰舒格兰二店）
A51: 17686603 | B51: 卖可便利店（皇山华府店） | G51: 17686603 | H51: 卖可便利店（皇山华府店）
A52: 5006858 | B52: 卖可便利店（豪森丽都店） | G52: 5006858 | H52: 卖可便利店（豪森丽都店）
A53: 11544311 | B53: 卖可便利店（曹王庄店） | G53: 11544311 | H53: 卖可便利店（曹王庄店）
A54: 18924392 | B54: 卖可便利店（宝丽财富广场店） | G54: 18924392 | H54: 卖可便利店（宝丽财富广场店）
A55: 14479252 | B55: 卖可便利店（一方上河府店） | G55: 14479252 | H55: 卖可便利店（一方上河府店）
A56: 7371577 | B56: 卖可便利店（华强领秀城店） | G56: 7371577 | H56: 卖可便利店（华强领秀城店）
A57: 21554691 | B57: 卖可便利店（第三人民医院店） | G57: 21554691 | H57: 卖可便利店（第三人民医院店）
... A182: 13145143 | B182: 卖可便利店（泰和花园店） | G182: 13145143 | H182: 卖可便利店（泰和花园店）
...

Sheet 重庆ID
A1: 平台 | B1: 渠道类型 | C1: 渠道名称 | D1: 终端美团ID
A2: 美团 | B2: 散店 | C2: 半达送酒（重庆渝北店） | D2: 21529415
A3: 美团 | B3: 散店 | C3: 京东便利店双骄便利店 | D3: 5523411
A4: 美团 | B4: 散店 | C4: 京东便利店（观音桥中心店） | D4: 18558812
A5: 美团 | B5: 散店 | C5: 臻酉品生活超市（融景城店） | D5: 120288331
A6: 美团 | B6: 散店 | C6: 考拉森活超市（江北店） | D6: 21405197
A7: 美团 | B7: 散店 | C7: 博利批发超市（渝北店） | D7: 17256106
A8: 美团 | B8: 散店 | C8: 聚品便利（二郎店） | D8: 19111065
A9: 美团 | B9: 散店 | C9: 信誉副食（水晶郦城店） | D9: 16382593
A10: 美团 | B10: 散店 | C10: 云商华夏粮仓超市（九龙店） | D10: 21117914
A11: 美团 | B11: 散店 | C11: 快购生活超市 | D11: 20869266
A12: 美团 | B12: 散店 | C12: 雾都生活超市 | D12: 17925618
A13: 美团 | B13: 散店 | C13: 芙蓉兴盛璧山东林店 | D13: 18666620
... A95: 美团 | B95: 散店 | C95: 明洪蔬菜配送 | D95: 10729383

Sheet 云南ID
A1: 省份 | B1: 城市 | C1: 商家ID | D1: 商家名称 | E1: 品牌名称
A2: 云南省 | B2: 昆明 | C2: 25880710 | D2: 齐易达便利（金江店） | E2: 大头24小时
A3: 云南省 | B3: 昆明 | C3: 14881558 | D3: 齐易达便利（高新店） | E3: 大头24小时
A4: 云南省 | B4: 昆明 | C4: 12097608 | D4: 齐易达便利（江苑店） | E4: 大头24小时
A5: 云南省 | B5: 大理白族自治州 | C5: 24090243 | D5: 江小囤·精品超市（大理店） | E5: 江小囤
A6: 云南省 | B6: 大理白族自治州 | C6: 28562106 | D6: 江小囤·精品超市（大理古城店） | E6: 江小囤
A7: 云南省 | B7: 昆明 | C7: 28456282 | D7: 江小囤·精品超市（教场西路店） | E7: 江小囤
A8: 云南省 | B8: 昆明 | C8: 20466440 | D8: 江小囤·精品超市（昆明店） | E8: 江小囤
A9: 云南省 | B9: 昆明 | C9: 25030253 | D9: 江小囤·精品超市（盘龙店） | E9: 江小囤
A10: 云南省 | B10: 昆明 | C10: 28456392 | D10: 江小囤·精品超市（同德店） | E10: 江小囤
A11: 云南省 | B11: 昆明 | C11: 21417260 | D11: 快捷购精品超市 | E11: 快捷购精品超市
A12: 云南省 | B12: 昭通 | C12: 27206254 | D12: 懒猫购连锁生活超市（锦海店） | E12: 懒猫购
A13: 云南省 | B13: 昭通 | C13: 29548933 | D13: 懒猫购连锁生活超市（学庄路店） | E13: 懒猫购
... A120: 云南省 | B120: 昆明 | C120: 100065786 | D120: 星马快送超市（西山店） | E120: 讯汇通
A121: 云南省 | B121: 大理白族自治州 | C121: 28636267 | D121: 犀牛百货（大理店） | E121: 犀牛百货
A122: 云南省 | B122: 昆明市 | C122: 28971299 | D122: 吉虎闪购 | E122: 吉虎闪购
A123: 云南省 | B123: 大理白族自治州 | C123: 1061884 | D123: 优品宅配洱海店 | E123: 优品宅配
A124: 云南省 | B124: 大理白族自治州 | C124: 15950193 | D124: 好客多 | E124: 好客多
A125: 云南省 | B125: 迪庆藏族自治州 | C125: 25628059 | D125: 万佳连锁超市（香格里拉店） | E125: 万佳连锁超市
A126: 云南省 | B126: 昆明 | C126: 24972999 | D126: 万佳连锁超市（官渡店） | E126: 万佳连锁超市
A127: 云南省 | B127: 昆明 | C127: 25774133 | D127: 万佳连锁超市（西山店） | E127: 万佳连锁超市
A128: 云南省 | B128: 曲靖 | C128: 21012233 | D128: 万佳连锁超市（曲靖店） | E128: 万佳连锁超市
A129: 云南省 | B129: 曲靖 | C129: 24118473 | D129: 万佳连锁超市（锦林花园店） | E129: 万佳连锁超市
A130: 云南省 | B130: 红河 | C130: 29867552 | D130: 万佳连锁超市(蒙自店) | E130: 万佳连锁超市
A131: 云南省 | B131: 昆明 | C131: 31251696 | D131: 星马快送超市（五华区店） | E131: 星马快送超市
A132: 云南省 | B132: 昆明 | C132: 31356105 | D132: 闪速熊甄选超市（昆明站店） | E132: 闪速熊甄选超市
A133: 云南省 | B133: 文山壮族苗族自治州 | C133: 31687673 | D133: 犀牛百货（文山店） | E133: 犀牛百货
